Workbook

Sheet ABSENSI
A4: No | B4: Nama | C4: Jabatan | D4: (0,50,100) % | E4: PRESTASI | F4: (0, 50)% | H4: (0, 50)% | I4: (0, 50)% | J4: JUMLAH | K4: JUMLAH | L4: JAM | M4: HARI | N4: HARI | P4: HARI | Q4: HARI | R4: S | S4: C | T4: I | U4: K | V4: JUMLAH | W4: =LEFT(TEXT(W5,"DDDD"),3) -> Kam | X4: =LEFT(TEXT(X5,"DDDD"),3) -> Jum | Y4: =LEFT(TEXT(Y5,"DDDD"),3) -> Sab | Z4: =LEFT(TEXT(Z5,"DDDD"),3) -> Min | AA4: =LEFT(TEXT(AA5,"DDDD"),3) -> Sen | AB4: =LEFT(TEXT(AB5,"DDDD"),3) -> Sel | AC4: =LEFT(TEXT(AC5,"DDDD"),3) -> Rab | AD4: =LEFT(TEXT(AD5,"DDDD"),3) -> Kam | ... AX4: =LEFT(TEXT(AX5,"DDDD"),3) -> Rab
D5: KEHADIRAN | E5: TOTAL | F5: PRESTASI | J5: KUNJUNGAN | K5: MENIT | L5: Lembur | M5: Bonus | N5: Setengah Hari | P5: PERHITUNGAN | Q5: EFEKTIF | R5: SAKIT | S5: CUTI | T5: IJIN | U5: KOSONG | V5: LIBUR | W5: 46079 | X5: 46080 | Y5: 46081 | Z5: 46082 | AA5: 46083 | AB5: 46084 | AC5: 46085 | AD5: 46086 | AE5: 46087 | AF5: 46088 | AG5: 46089 | AH5: 46090 | AI5: 46091 | AJ5: 46092 | AK5: 46093 | AL5: 46094 | AM5: 46095 | AN5: 46096 | AO5: 46097 | AP5: 46098 | AQ5: 46099 | AR5: 46100 | AS5: 46101 | AT5: 46102 | AU5: 46103 | AV5: 46104 | AW5: 46105 | AX5: 46106
B6: Nama | C6: Jabatan | D6: KEHADIRAN | E6: PRESTASI | F6: GROOMING | G6: GROOM | H6: COMPLAIN | I6: COM | J6: KUNJUNGAN | K6: JAM | L6: Lembur | M6: HARI | N6: HARI | P6: HARI | Q6: HARI | R6: S | S6: C | T6: I
A7: 1 | B7: Robby Anggoro | C7: Teknisi Station | D7: =IF(KEHADIRAN!$E$7:$E$106>=2,"0",IF(KEHADIRAN!$E$7:$E$106>=1,"50%",IF(KEHADIRAN!$E$7:$E$106<=0,"100%"))) -> 100% | E7: =F7+H7 -> 1 | F7: =IF(G7:G36>=2,"0",IF(G7:G36>=1,"0",IF(G7:G36<=0,"50%"))) -> 50% | G7: =SUMIFS(GROOMING!$B$4:$B$231,GROOMING!$C$4:$C$231,ABSENSI!B7) -> 0 | H7: =IF(I7:I36>=2,"0",IF(I7:I36>=1,"0",IF(I7:I36<=0,"50%"))) -> 50% | I7: =SUMIFS(COMPLAIN!$B$4:$B$231,COMPLAIN!$F$4:$F$231,ABSENSI!B7) -> 0 | J7: =SUMIFS(KUNJUNGAN!$C$4:$C$800,KUNJUNGAN!$B$4:$B$800,ABSENSI!$B7) -> 0 | K7: =SUMIFS(KUNJUNGAN!$J$4:$J$800,KUNJUNGAN!$B$4:$B$800,ABSENSI!$B7) -> 0 | L7: =SUMIFS(LEMBUR!$F$4:$F$235,LEMBUR!$B$4:$B$235,ABSENSI!$B7) -> 0 | M7: =COUNTIF(R7:BA7,"√√")+COUNTIF(R7:BA7,"X/") -> 0 | N7: =COUNTIF(S7:BA7,"√/") -> 0 | O7: =N7*0.5 -> 0 | P7: =SUM(Q7:S7)+O7 -> 22 | Q7: =(COUNTIF(W7:BA7,"√"))+(COUNTIF(W7:BA7,"√√")) -> 19 | R7: =COUNTIF(W7:BA7,"s") -> 0 | S7: =COUNTIF(W7:BA7,"c") -> 3 | T7: =COUNTIF(W7:BA7,"i") -> 0 | U7: =COUNTIF(W7:BA7,"") -> 3 | V7: =COUNTIF(W7:BA7,"X") -> 6 | W7: √ | X7: √ | Y7: √ | Z7: X | AA7: √ | AB7: √ | AC7: √ | AD7: √ | AE7: √ | AF7: √ | AG7: X | AH7: √ | AI7: √ | AJ7: √ | AK7: √ | AL7: √ | AM7: X | AN7: √ | AO7: √ | AP7: √ | AQ7: √ | AR7: √ | AS7: X | AT7: X | AU7: X | AV7: C | AW7: C | AX7: C
A8: 2 | B8: Ita Ernia | C8: Personalia | D8: =IF(KEHADIRAN!$E$7:$E$106>=2,"0",IF(KEHADIRAN!$E$7:$E$106>=1,"50%",IF(KEHADIRAN!$E$7:$E$106<=0,"100%"))) -> 100% | E8: =F7+H7 -> 1 | F8: =IF(G8:G42>=2,"0",IF(G8:G42>=1,"0",IF(G8:G42<=0,"50%"))) -> 50% | H8: =IF(I8:I42>=2,"0",IF(I8:I42>=1,"0",IF(I8:I42<=0,"50%"))) -> 50% | I8: =SUMIFS(COMPLAIN!$B$4:$B$231,COMPLAIN!$F$4:$F$231,ABSENSI!B8) -> 0 | J8: =SUMIFS(KUNJUNGAN!$C$4:$C$800,KUNJUNGAN!$B$4:$B$800,ABSENSI!$B8) -> 0 | K8: =SUMIFS(KUNJUNGAN!$J$4:$J$800,KUNJUNGAN!$B$4:$B$800,ABSENSI!$B8) -> 0 | L8: =SUMIFS(LEMBUR!$F$4:$F$235,LEMBUR!$B$4:$B$235,ABSENSI!$B8) -> 0 | M8: =COUNTIF(R8:BA8,"√√")+COUNTIF(R8:BA8,"X/") -> 0 | N8: =COUNTIF(S8:BA8,"√/") -> 0 | O8: =N8*0.5 -> 0 | P8: =SUM(Q8:S8)+O8 -> 22 | Q8: =(COUNTIF(W8:BA8,"√"))+(COUNTIF(W8:BA8,"√√")) -> 18 | R8: =COUNTIF(W8:BA8,"s") -> 0 | S8: =COUNTIF(W8:BA8,"c") -> 4 | T8: =COUNTIF(W8:BA8,"i") -> 0 | U8: =COUNTIF(W8:BA8,"") -> 3 | V8: =COUNTIF(W8:BA8,"X") -> 6 | W8: √ | X8: √ | Y8: √ | Z8: X | AA8: √ | AB8: √ | AC8: √ | AD8: √ | AE8: √ | AF8: √ | AG8: X | AH8: √ | AI8: √ | AJ8: √ | AK8: √ | AL8: √ | AM8: √ | AN8: X | AO8: √ | AP8: √ | AQ8: C | AR8: X | AS8: C | AT8: X | AU8: X | AV8: C | AW8: C | AX8: √
A9: 3 | B9: Choirul Anam | C9: Teknisi Mobile | D9: =IF(KEHADIRAN!$E$7:$E$106>=2,"0",IF(KEHADIRAN!$E$7:$E$106>=1,"50%",IF(KEHADIRAN!$E$7:$E$106<=0,"100%"))) -> 100% | E9: =F9+H9 -> 1 | F9: =IF(G9:G38>=2,"0",IF(G9:G38>=1,"0",IF(G9:G38<=0,"50%"))) -> 50% | G9: =SUMIFS(GROOMING!$B$4:$B$231,GROOMING!$C$4:$C$231,ABSENSI!B9) -> 0 | H9: =IF(I9:I38>=2,"0",IF(I9:I38>=1,"0",IF(I9:I38<=0,"50%"))) -> 50% | I9: =SUMIFS(COMPLAIN!$B$4:$B$231,COMPLAIN!$F$4:$F$231,ABSENSI!B9) -> 0 | J9: =SUMIFS(KUNJUNGAN!$C$4:$C$800,KUNJUNGAN!$B$4:$B$800,ABSENSI!$B9) -> 54 | K9: =SUMIFS(KUNJUNGAN!$J$4:$J$800,KUNJUNGAN!$B$4:$B$800,ABSENSI!$B9) -> 4226 | L9: =SUMIFS(LEMBUR!$F$4:$F$235,LEMBUR!$B$4:$B$235,ABSENSI!$B9) -> 0 | M9: =COUNTIF(R9:BA9,"√√")+COUNTIF(R9:BA9,"X/") -> 0 | N9: =COUNTIF(S9:BA9,"√/") -> 0 | O9: =N9*0.5 -> 0 | P9: =SUM(Q9:S9)+O9 -> 22 | Q9: =(COUNTIF(W9:BA9,"√"))+(COUNTIF(W9:BA9,"√√")) -> 20 | R9: =COUNTIF(W9:BA9,"s") -> 0 | S9: =COUNTIF(W9:BA9,"c") -> 2 | T9: =COUNTIF(W9:BA9,"i") -> 0 | U9: =COUNTIF(W9:BA9,"") -> 3 | V9: =COUNTIF(W9:BA9,"X") -> 6 | W9: √ | X9: √ | Y9: √ | Z9: X | AA9: √ | AB9: √ | AC9: √ | AD9: √ | AE9: √ | AF9: √ | AG9: X | AH9: √ | AI9: √ | AJ9: √ | AK9: √ | AL9: √ | AM9: √ | AN9: X | AO9: √ | AP9: √ | AQ9: √ | AR9: X | AS9: C | AT9: X | AU9: X | AV9: C | AW9: √ | AX9: √
A10: 4 | B10: Moch Anis Fathony | C10: Supervisor | D10: =IF(KEHADIRAN!$E$7:$E$106>=2,"0",IF(KEHADIRAN!$E$7:$E$106>=1,"50%",IF(KEHADIRAN!$E$7:$E$106<=0,"100%"))) -> 100% | E10: =F10+H10 -> 1 | F10: =IF(G10:G44>=2,"0",IF(G10:G44>=1,"0",IF(G10:G44<=0,"50%"))) -> 50% | H10: =IF(I10:I44>=2,"0",IF(I10:I44>=1,"0",IF(I10:I44<=0,"50%"))) -> 50% | I10: =SUMIFS(COMPLAIN!$B$4:$B$231,COMPLAIN!$F$4:$F$231,ABSENSI!B10) -> 0 | J10: =SUMIFS(KUNJUNGAN!$C$4:$C$800,KUNJUNGAN!$B$4:$B$800,ABSENSI!$B10) -> 0 | K10: =SUMIFS(KUNJUNGAN!$J$4:$J$800,KUNJUNGAN!$B$4:$B$800,ABSENSI!$B10) -> 0 | L10: =SUMIFS(LEMBUR!$F$4:$F$235,LEMBUR!$B$4:$B$235,ABSENSI!$B10) -> 0 | M10: =COUNTIF(R10:BA10,"√√")+COUNTIF(R10:BA10,"X/") -> 0 | N10: =COUNTIF(S10:BA10,"√/") -> 0 | O10: =N10*0.5 -> 0 | P10: =SUM(Q10:S10)+O10 -> 22 | Q10: =(COUNTIF(W10:BA10,"√"))+(COUNTIF(W10:BA10,"√√")) -> 18 | R10: =COUNTIF(W10:BA10,"s") -> 0 | S10: =COUNTIF(W10:BA10,"c") -> 4 | T10: =COUNTIF(W10:BA10,"i") -> 0 | U10: =COUNTIF(W10:BA10,"") -> 3 | V10: =COUNTIF(W10:BA10,"X") -> 6 | W10: √ | X10: √ | Y10: C | Z10: X | AA10: C | AB10: √ | AC10: √ | AD10: √ | AE10: √ | AF10: √ | AG10: X | AH10: √ | AI10: √ | AJ10: √ | AK10: √ | AL10: √ | AM10: √ | AN10: X | AO10: √ | AP10: √ | AQ10: √ | AR10: X | AS10: C | AT10: X | AU10: X | AV10: C | AW10: √ | AX10: √
A11: 5 | B11: Sulistiono | C11: Teknisi Station | D11: =IF(KEHADIRAN!$E$7:$E$106>=2,"0",IF(KEHADIRAN!$E$7:$E$106>=1,"50%",IF(KEHADIRAN!$E$7:$E$106<=0,"100%"))) -> 100% | E11: =F11+H11 -> 1 | F11: =IF(G11:G40>=2,"0",IF(G11:G40>=1,"0",IF(G11:G40<=0,"50%"))) -> 50% | G11: =SUMIFS(GROOMING!$B$4:$B$231,GROOMING!$C$4:$C$231,ABSENSI!B11) -> 0 | H11: =IF(I11:I40>=2,"0",IF(I11:I40>=1,"0",IF(I11:I40<=0,"50%"))) -> 50% | I11: =SUMIFS(COMPLAIN!$B$4:$B$231,COMPLAIN!$F$4:$F$231,ABSENSI!B11) -> 0 | J11: =SUMIFS(KUNJUNGAN!$C$4:$C$800,KUNJUNGAN!$B$4:$B$800,ABSENSI!$B11) -> 0 | K11: =SUMIFS(KUNJUNGAN!$J$4:$J$800,KUNJUNGAN!$B$4:$B$800,ABSENSI!$B11) -> 0 | L11: =SUMIFS(LEMBUR!$F$4:$F$235,LEMBUR!$B$4:$B$235,ABSENSI!$B11) -> 0 | M11: =COUNTIF(R11:BA11,"√√")+COUNTIF(R11:BA11,"X/") -> 0 | N11: =COUNTIF(S11:BA11,"√/") -> 0 | O11: =N11*0.5 -> 0 | P11: =SUM(Q11:S11)+O11 -> 23 | Q11: =(COUNTIF(W11:BA11,"√"))+(COUNTIF(W11:BA11,"√√")) -> 23 | R11: =COUNTIF(W11:BA11,"s") -> 0 | S11: =COUNTIF(W11:BA11,"c") -> 0 | T11: =COUNTIF(W11:BA11,"i") -> 0 | U11: =COUNTIF(W11:BA11,"") -> 3 | V11: =COUNTIF(W11:BA11,"X") -> 5 | W11: √ | X11: √ | Y11: √ | Z11: X | AA11: √ | AB11: √ | AC11: √ | AD11: √ | AE11: √ | AF11: √ | AG11: X | AH11: √ | AI11: √ | AJ11: √ | AK11: √ | AL11: √ | AM11: √ | AN11: X | AO11: √ | AP11: √ | AQ11: √ | AR11: √ | AS11: √ | AT11: √ | AU11: X | AV11: X | AW11: √ | AX11: √
A12: 6 | B12: Akbar Rohmatulah | C12: Teknisi Mobile | D12: =IF(KEHADIRAN!$E$7:$E$106>=2,"0",IF(KEHADIRAN!$E$7:$E$106>=1,"50%",IF(KEHADIRAN!$E$7:$E$106<=0,"100%"))) -> 100% | E12: =F11+H11 -> 1 | F12: =IF(G12:G46>=2,"0",IF(G12:G46>=1,"0",IF(G12:G46<=0,"50%"))) -> 50% | H12: =IF(I12:I46>=2,"0",IF(I12:I46>=1,"0",IF(I12:I46<=0,"50%"))) -> 50% | I12: =SUMIFS(COMPLAIN!$B$4:$B$231,COMPLAIN!$F$4:$F$231,ABSENSI!B12) -> 0 | J12: =SUMIFS(KUNJUNGAN!$C$4:$C$800,KUNJUNGAN!$B$4:$B$800,ABSENSI!$B12) -> 58 | K12: =SUMIFS(KUNJUNGAN!$J$4:$J$800,KUNJUNGAN!$B$4:$B$800,ABSENSI!$B12) -> 5736 | L12: =SUMIFS(LEMBUR!$F$4:$F$235,LEMBUR!$B$4:$B$235,ABSENSI!$B12) -> 0 | M12: =COUNTIF(R12:BA12,"√√")+COUNTIF(R12:BA12,"X/") -> 0 | N12: =COUNTIF(S12:BA12,"√/") -> 0 | O12: =N12*0.5 -> 0 | P12: =SUM(Q12:S12)+O12 -> 22 | Q12: =(COUNTIF(W12:BA12,"√"))+(COUNTIF(W12:BA12,"√√")) -> 20 | R12: =COUNTIF(W12:BA12,"s") -> 0 | S12: =COUNTIF(W12:BA12,"c") -> 2 | T12: =COUNTIF(W12:BA12,"i") -> 0 | U12: =COUNTIF(W12:BA12,"") -> 3 | V12: =COUNTIF(W12:BA12,"X") -> 6 | W12: √ | X12: √ | Y12: √ | Z12: X | AA12: √ | AB12: √ | AC12: √ | AD12: √ | AE12: √ | AF12: √ | AG12: X | AH12: √ | AI12: √ | AJ12: √ | AK12: √ | AL12: √ | AM12: √ | AN12: X | AO12: √ | AP12: √ | AQ12: √ | AR12: X | AS12: C | AT12: X | AU12: X | AV12: C | AW12: √ | AX12: √
A13: 7 | B13: Suparman | C13: Teknisi Station | D13: =IF(KEHADIRAN!$E$7:$E$106>=2,"0",IF(KEHADIRAN!$E$7:$E$106>=1,"50%",IF(KEHADIRAN!$E$7:$E$106<=0,"100%"))) -> 100% | E13: =F13+H13 -> 1 | F13: =IF(G13:G42>=2,"0",IF(G13:G42>=1,"0",IF(G13:G42<=0,"50%"))) -> 50% | G13: =SUMIFS(GROOMING!$B$4:$B$231,GROOMING!$C$4:$C$231,ABSENSI!B13) -> 0 | H13: =IF(I13:I42>=2,"0",IF(I13:I42>=1,"0",IF(I13:I42<=0,"50%"))) -> 50% | I13: =SUMIFS(COMPLAIN!$B$4:$B$231,COMPLAIN!$F$4:$F$231,ABSENSI!B13) -> 0 | J13: =SUMIFS(KUNJUNGAN!$C$4:$C$800,KUNJUNGAN!$B$4:$B$800,ABSENSI!$B13) -> 0 | K13: =SUMIFS(KUNJUNGAN!$J$4:$J$800,KUNJUNGAN!$B$4:$B$800,ABSENSI!$B13) -> 0 | L13: =SUMIFS(LEMBUR!$F$4:$F$235,LEMBUR!$B$4:$B$235,ABSENSI!$B13) -> 3 | M13: =COUNTIF(R13:BA13,"√√")+COUNTIF(R13:BA13,"X/") -> 0 | N13: =COUNTIF(S13:BA13,"√/") -> 0 | O13: =N13*0.5 -> 0 | P13: =SUM(Q13:S13)+O13 -> 21 | Q13: =(COUNTIF(W13:BA13,"√"))+(COUNTIF(W13:BA13,"√√")) -> 21 | R13: =COUNTIF(W13:BA13,"s") -> 0 | S13: =COUNTIF(W13:BA13,"c") -> 0 | T13: =COUNTIF(W13:BA13,"i") -> 0 | U13: =COUNTIF(W13:BA13,"") -> 3 | V13: =COUNTIF(W13:BA13,"X") -> 7 | W13: X | X13: √ | Y13: √ | Z13: X | AA13: √ | AB13: √ | AC13: √ | AD13: √ | AE13: √ | AF13: √ | AG13: X | AH13: √ | AI13: √ | AJ13: √ | AK13: √ | AL13: √ | AM13: √ | AN13: X | AO13: √ | AP13: √ | AQ13: √ | AR13: √ | AS13: √ | AT13: X | AU13: X | AV13: X | AW13: √ | AX13: √
A14: 8 | B14: Hendra Mulalinda | C14: Koor TC | D14: =IF(KEHADIRAN!$E$7:$E$106>=2,"0",IF(KEHADIRAN!$E$7:$E$106>=1,"50%",IF(KEHADIRAN!$E$7:$E$106<=0,"100%"))) -> 100% | E14: =F13+H13 -> 1 | F14: =IF(G14:G48>=2,"0",IF(G14:G48>=1,"0",IF(G14:G48<=0,"50%"))) -> 50% | H14: =IF(I14:I48>=2,"0",IF(I14:I48>=1,"0",IF(I14:I48<=0,"50%"))) -> 50% | I14: =SUMIFS(COMPLAIN!$B$4:$B$231,COMPLAIN!$F$4:$F$231,ABSENSI!B14) -> 0 | J14: =SUMIFS(KUNJUNGAN!$C$4:$C$800,KUNJUNGAN!$B$4:$B$800,ABSENSI!$B14) -> 0 | K14: =SUMIFS(KUNJUNGAN!$J$4:$J$800,KUNJUNGAN!$B$4:$B$800,ABSENSI!$B14) -> 0 | L14: =SUMIFS(LEMBUR!$F$4:$F$235,LEMBUR!$B$4:$B$235,ABSENSI!$B14) -> 19 | M14: =COUNTIF(R14:BA14,"√√")+COUNTIF(R14:BA14,"X/") -> 0 | N14: =COUNTIF(S14:BA14,"√/") -> 0 | O14: =N14*0.5 -> 0 | P14: =SUM(Q14:S14)+O14 -> 22 | Q14: =(COUNTIF(W14:BA14,"√"))+(COUNTIF(W14:BA14,"√√")) -> 19 | R14: =COUNTIF(W14:BA14,"s") -> 0 | S14: =COUNTIF(W14:BA14,"c") -> 3 | T14: =COUNTIF(W14:BA14,"i") -> 0 | U14: =COUNTIF(W14:BA14,"") -> 3 | V14: =COUNTIF(W14:BA14,"X") -> 6 | W14: √ | X14: √ | Y14: √ | Z14: X | AA14: √ | AB14: √ | AC14: √ | AD14: √ | AE14: √ | AF14: X | AG14: √ | AH14: √ | AI14: √ | AJ14: √ | AK14: √ | AL14: √ | AM14: √ | AN14: X | AO14: √ | AP14: √ | AQ14: √ | AR14: X | AS14: C | AT14: X | AU14: X | AV14: C | AW14: C | AX14: √
A15: 9 | B15: Moh. Mahrus | C15: Teknisi Mobile | D15: =IF(KEHADIRAN!$E$7:$E$106>=2,"0",IF(KEHADIRAN!$E$7:$E$106>=1,"50%",IF(KEHADIRAN!$E$7:$E$106<=0,"100%"))) -> 100% | E15: =F15+H15 -> 1 | F15: =IF(G15:G44>=2,"0",IF(G15:G44>=1,"0",IF(G15:G44<=0,"50%"))) -> 50% | G15: =SUMIFS(GROOMING!$B$4:$B$231,GROOMING!$C$4:$C$231,ABSENSI!B15) -> 0 | H15: =IF(I15:I44>=2,"0",IF(I15:I44>=1,"0",IF(I15:I44<=0,"50%"))) -> 50% | I15: =SUMIFS(COMPLAIN!$B$4:$B$231,COMPLAIN!$F$4:$F$231,ABSENSI!B15) -> 0 | J15: =SUMIFS(KUNJUNGAN!$C$4:$C$800,KUNJUNGAN!$B$4:$B$800,ABSENSI!$B15) -> 51 | K15: =SUMIFS(KUNJUNGAN!$J$4:$J$800,KUNJUNGAN!$B$4:$B$800,ABSENSI!$B15) -> 4425 | L15: =SUMIFS(LEMBUR!$F$4:$F$235,LEMBUR!$B$4:$B$235,ABSENSI!$B15) -> 0 | M15: =COUNTIF(R15:BA15,"√√")+COUNTIF(R15:BA15,"X/") -> 0 | N15: =COUNTIF(S15:BA15,"√/") -> 0 | O15: =N15*0.5 -> 0 | P15: =SUM(Q15:S15)+O15 -> 21 | Q15: =(COUNTIF(W15:BA15,"√"))+(COUNTIF(W15:BA15,"√√")) -> 19 | R15: =COUNTIF(W15:BA15,"s") -> 0 | S15: =COUNTIF(W15:BA15,"c") -> 2 | T15: =COUNTIF(W15:BA15,"i") -> 1 | U15: =COUNTIF(W15:BA15,"") -> 3 | V15: =COUNTIF(W15:BA15,"X") -> 6 | W15: √ | X15: √ | Y15: √ | Z15: X | AA15: √ | AB15: √ | AC15: √ | AD15: √ | AE15: √ | AF15: √ | AG15: X | AH15: √ | AI15: √ | AJ15: √ | AK15: I | AL15: √ | AM15: √ | AN15: X | AO15: √ | AP15: √ | AQ15: √ | AR15: X | AS15: C | AT15: X | AU15: X | AV15: C | AW15: √ | AX15: √
A16: 10 | B16: Rohandy Sujoko | C16: Teknisi Termite | D16: =IF(KEHADIRAN!$E$7:$E$106>=2,"0",IF(KEHADIRAN!$E$7:$E$106>=1,"50%",IF(KEHADIRAN!$E$7:$E$106<=0,"100%"))) -> 100% | E16: =F15+H15 -> 1 | F16: =IF(G16:G50>=2,"0",IF(G16:G50>=1,"0",IF(G16:G50<=0,"50%"))) -> 50% | H16: =IF(I16:I50>=2,"0",IF(I16:I50>=1,"0",IF(I16:I50<=0,"50%"))) -> 50% | I16: =SUMIFS(COMPLAIN!$B$4:$B$231,COMPLAIN!$F$4:$F$231,ABSENSI!B16) -> 0 | J16: =SUMIFS(KUNJUNGAN!$C$4:$C$800,KUNJUNGAN!$B$4:$B$800,ABSENSI!$B16) -> 0 | K16: =SUMIFS(KUNJUNGAN!$J$4:$J$800,KUNJUNGAN!$B$4:$B$800,ABSENSI!$B16) -> 0 | L16: =SUMIFS(LEMBUR!$F$4:$F$235,LEMBUR!$B$4:$B$235,ABSENSI!$B16) -> 10 | M16: =COUNTIF(R16:BA16,"√√")+COUNTIF(R16:BA16,"X/") -> 0 | N16: =COUNTIF(S16:BA16,"√/") -> 0 | O16: =N16*0.5 -> 0 | P16: =SUM(Q16:S16)+O16 -> 21 | Q16: =(COUNTIF(W16:BA16,"√"))+(COUNTIF(W16:BA16,"√√")) -> 18 | R16: =COUNTIF(W16:BA16,"s") -> 1 | S16: =COUNTIF(W16:BA16,"c") -> 2 | T16: =COUNTIF(W16:BA16,"i") -> 1 | U16: =COUNTIF(W16:BA16,"") -> 3 | V16: =COUNTIF(W16:BA16,"X") -> 6 | W16: √ | X16: √ | Y16: √ | Z16: X | AA16: √ | AB16: √ | AC16: √ | AD16: √ | AE16: √ | AF16: X | AG16: √ | AH16: S | AI16: I | AJ16: √ | AK16: √ | AL16: √ | AM16: √ | AN16: X | AO16: √ | AP16: √ | AQ16: √ | AR16: X | AS16: C | AT16: X | AU16: X | AV16: C | AW16: √ | AX16: √
A17: 11 | B17: Lucky Adi Putra | C17: Teknisi Mobile | D17: =IF(KEHADIRAN!$E$7:$E$106>=2,"0",IF(KEHADIRAN!$E$7:$E$106>=1,"50%",IF(KEHADIRAN!$E$7:$E$106<=0,"100%"))) -> 100% | E17: =F17+H17 -> 1 | F17: =IF(G17:G46>=2,"0",IF(G17:G46>=1,"0",IF(G17:G46<=0,"50%"))) -> 50% | G17: =SUMIFS(GROOMING!$B$4:$B$231,GROOMING!$C$4:$C$231,ABSENSI!B17) -> 0 | H17: =IF(I17:I46>=2,"0",IF(I17:I46>=1,"0",IF(I17:I46<=0,"50%"))) -> 50% | I17: =SUMIFS(COMPLAIN!$B$4:$B$231,COMPLAIN!$F$4:$F$231,ABSENSI!B17) -> 0 | J17: =SUMIFS(KUNJUNGAN!$C$4:$C$800,KUNJUNGAN!$B$4:$B$800,ABSENSI!$B17) -> 60 | K17: =SUMIFS(KUNJUNGAN!$J$4:$J$800,KUNJUNGAN!$B$4:$B$800,ABSENSI!$B17) -> 5702 | L17: =SUMIFS(LEMBUR!$F$4:$F$235,LEMBUR!$B$4:$B$235,ABSENSI!$B17) -> 0 | M17: =COUNTIF(R17:BA17,"√√")+COUNTIF(R17:BA17,"X/") -> 0 | N17: =COUNTIF(S17:BA17,"√/") -> 0 | O17: =N17*0.5 -> 0 | P17: =SUM(Q17:S17)+O17 -> 22 | Q17: =(COUNTIF(W17:BA17,"√"))+(COUNTIF(W17:BA17,"√√")) -> 20 | R17: =COUNTIF(W17:BA17,"s") -> 0 | S17: =COUNTIF(W17:BA17,"c") -> 2 | T17: =COUNTIF(W17:BA17,"i") -> 0 | U17: =COUNTIF(W17:BA17,"") -> 3 | V17: =COUNTIF(W17:BA17,"X") -> 6 | W17: √ | X17: √ | Y17: √ | Z17: X | AA17: √ | AB17: √ | AC17: √ | AD17: √ | AE17: √ | AF17: √ | AG17: X | AH17: √ | AI17: √ | AJ17: √ | AK17: √ | AL17: √ | AM17: √ | AN17: X | AO17: √ | AP17: √ | AQ17: √ | AR17: X | AS17: C | AT17: X | AU17: X | AV17: C | AW17: √ | AX17: √
A18: 12 | B18: Siti Lutfiani | C18: Admin F&A | D18: =IF(KEHADIRAN!$E$7:$E$106>=2,"0",IF(KEHADIRAN!$E$7:$E$106>=1,"50%",IF(KEHADIRAN!$E$7:$E$106<=0,"100%"))) -> 100% | E18: =F17+H17 -> 1 | F18: =IF(G18:G65>=2,"0",IF(G18:G65>=1,"0",IF(G18:G65<=0,"50%"))) -> 50% | H18: =IF(I18:I65>=2,"0",IF(I18:I65>=1,"0",IF(I18:I65<=0,"50%"))) -> 50% | I18: =SUMIFS(COMPLAIN!$B$4:$B$231,COMPLAIN!$F$4:$F$231,ABSENSI!B18) -> 0 | J18: =SUMIFS(KUNJUNGAN!$C$4:$C$800,KUNJUNGAN!$B$4:$B$800,ABSENSI!$B18) -> 0 | K18: =SUMIFS(KUNJUNGAN!$J$4:$J$800,KUNJUNGAN!$B$4:$B$800,ABSENSI!$B18) -> 0 | L18: =SUMIFS(LEMBUR!$F$4:$F$235,LEMBUR!$B$4:$B$235,ABSENSI!$B18) -> 0 | M18: =COUNTIF(R18:BA18,"√√")+COUNTIF(R18:BA18,"X/") -> 0 | N18: =COUNTIF(S18:BA18,"√/") -> 0 | O18: =N18*0.5 -> 0 | P18: =SUM(Q18:S18)+O18 -> 22 | Q18: =(COUNTIF(W18:BA18,"√"))+(COUNTIF(W18:BA18,"√√")) -> 18 | R18: =COUNTIF(W18:BA18,"s") -> 0 | S18: =COUNTIF(W18:BA18,"c") -> 4 | T18: =COUNTIF(W18:BA18,"i") -> 0 | U18: =COUNTIF(W18:BA18,"") -> 3 | V18: =COUNTIF(W18:BA18,"X") -> 6 | W18: √ | X18: √ | Y18: √ | Z18: X | AA18: √ | AB18: √ | AC18: √ | AD18: √ | AE18: √ | AF18: √ | AG18: X | AH18: √ | AI18: √ | AJ18: √ | AK18: √ | AL18: √ | AM18: √ | AN18: X | AO18: √ | AP18: √ | AQ18: √ | AR18: X | AS18: C | AT18: X | AU18: X | AV18: C | AW18: C | AX18: C
A19: 13 | B19: Andik Noroyan Fananiar | C19: Teknisi Mobile | D19: =IF(KEHADIRAN!$E$7:$E$106>=2,"0",IF(KEHADIRAN!$E$7:$E$106>=1,"50%",IF(KEHADIRAN!$E$7:$E$106<=0,"100%"))) -> 100% | E19: =F19+H19 -> 1 | F19: =IF(G19:G48>=2,"0",IF(G19:G48>=1,"0",IF(G19:G48<=0,"50%"))) -> 50% | G19: =SUMIFS(GROOMING!$B$4:$B$231,GROOMING!$C$4:$C$231,ABSENSI!B19) -> 0 | H19: =IF(I19:I48>=2,"0",IF(I19:I48>=1,"0",IF(I19:I48<=0,"50%"))) -> 50% | I19: =SUMIFS(COMPLAIN!$B$4:$B$231,COMPLAIN!$F$4:$F$231,ABSENSI!B19) -> 0 | J19: =SUMIFS(KUNJUNGAN!$C$4:$C$800,KUNJUNGAN!$B$4:$B$800,ABSENSI!$B19) -> 54 | K19: =SUMIFS(KUNJUNGAN!$J$4:$J$800,KUNJUNGAN!$B$4:$B$800,ABSENSI!$B19) -> 5496 | L19: =SUMIFS(LEMBUR!$F$4:$F$235,LEMBUR!$B$4:$B$235,ABSENSI!$B19) -> 0 | M19: =COUNTIF(R19:BA19,"√√")+COUNTIF(R19:BA19,"X/") -> 0 | N19: =COUNTIF(S19:BA19,"√/") -> 0 | O19: =N19*0.5 -> 0 | P19: =SUM(Q19:S19)+O19 -> 22 | Q19: =(COUNTIF(W19:BA19,"√"))+(COUNTIF(W19:BA19,"√√")) -> 20 | R19: =COUNTIF(W19:BA19,"s") -> 0 | S19: =COUNTIF(W19:BA19,"c") -> 2 | T19: =COUNTIF(W19:BA19,"i") -> 0 | U19: =COUNTIF(W19:BA19,"") -> 3 | V19: =COUNTIF(W19:BA19,"X") -> 6 | W19: √ | X19: √ | Y19: √ | Z19: √ | AA19: √ | AB19: √ | AC19: X | AD19: √ | AE19: √ | AF19: √ | AG19: √ | AH19: √ | AI19: √ | AJ19: X | AK19: √ | AL19: √ | AM19: √ | AN19: √ | AO19: √ | AP19: √ | AQ19: √ | AR19: X | AS19: C | AT19: X | AU19: X | AV19: C | AW19: X | AX19: √
A20: 14 | B20: Muhammad Abu Samsudin | C20: Teknisi Mobile | D20: =IF(KEHADIRAN!$E$7:$E$106>=2,"0",IF(KEHADIRAN!$E$7:$E$106>=1,"50%",IF(KEHADIRAN!$E$7:$E$106<=0,"100%"))) -> 100% | E20: =F19+H19 -> 1 | F20: =IF(G20:G68>=2,"0",IF(G20:G68>=1,"0",IF(G20:G68<=0,"50%"))) -> 50% | H20: =IF(I20:I68>=2,"0",IF(I20:I68>=1,"0",IF(I20:I68<=0,"50%"))) -> 50% | I20: =SUMIFS(COMPLAIN!$B$4:$B$231,COMPLAIN!$F$4:$F$231,ABSENSI!B20) -> 0 | J20: =SUMIFS(KUNJUNGAN!$C$4:$C$800,KUNJUNGAN!$B$4:$B$800,ABSENSI!$B20) -> 50 | K20: =SUMIFS(KUNJUNGAN!$J$4:$J$800,KUNJUNGAN!$B$4:$B$800,ABSENSI!$B20) -> 7072 | L20: =SUMIFS(LEMBUR!$F$4:$F$235,LEMBUR!$B$4:$B$235,ABSENSI!$B20) -> 0 | M20: =COUNTIF(R20:BA20,"√√")+COUNTIF(R20:BA20,"X/") -> 0 | N20: =COUNTIF(S20:BA20,"√/") -> 0 | O20: =N20*0.5 -> 0 | P20: =SUM(Q20:S20)+O20 -> 22 | Q20: =(COUNTIF(W20:BA20,"√"))+(COUNTIF(W20:BA20,"√√")) -> 21 | R20: =COUNTIF(W20:BA20,"s") -> 0 | S20: =COUNTIF(W20:BA20,"c") -> 1 | T20: =COUNTIF(W20:BA20,"i") -> 0 | U20: =COUNTIF(W20:BA20,"") -> 3 | V20: =COUNTIF(W20:BA20,"X") -> 6 | W20: √ | X20: √ | Y20: X | Z20: √ | AA20: √ | AB20: √ | AC20: √ | AD20: √ | AE20: √ | AF20: X | AG20: √ | AH20: √ | AI20: √ | AJ20: √ | AK20: √ | AL20: √ | AM20: X | AN20: √ | AO20: √ | AP20: √ | AQ20: √ | AR20: √ | AS20: X | AT20: X | AU20: X | AV20: C | AW20: √ | AX20: √
A21: 15 | B21: Imelynia Pratiwi Suhari | C21: QC & Koor PRC | D21: =IF(KEHADIRAN!$E$7:$E$106>=2,"0",IF(KEHADIRAN!$E$7:$E$106>=1,"50%",IF(KEHADIRAN!$E$7:$E$106<=0,"100%"))) -> 100% | E21: =F21+H21 -> 1 | F21: =IF(G21:G50>=2,"0",IF(G21:G50>=1,"0",IF(G21:G50<=0,"50%"))) -> 50% | G21: =SUMIFS(GROOMING!$B$4:$B$231,GROOMING!$C$4:$C$231,ABSENSI!B21) -> 0 | H21: =IF(I21:I50>=2,"0",IF(I21:I50>=1,"0",IF(I21:I50<=0,"50%"))) -> 50% | I21: =SUMIFS(COMPLAIN!$B$4:$B$231,COMPLAIN!$F$4:$F$231,ABSENSI!B21) -> 0 | J21: =SUMIFS(KUNJUNGAN!$C$4:$C$800,KUNJUNGAN!$B$4:$B$800,ABSENSI!$B21) -> 0 | K21: =SUMIFS(KUNJUNGAN!$J$4:$J$800,KUNJUNGAN!$B$4:$B$800,ABSENSI!$B21) -> 0 | L21: =SUMIFS(LEMBUR!$F$4:$F$235,LEMBUR!$B$4:$B$235,ABSENSI!$B21) -> 0 | M21: =COUNTIF(R21:BA21,"√√")+COUNTIF(R21:BA21,"X/") -> 0 | N21: =COUNTIF(S21:BA21,"√/") -> 1 | O21: =N21*0.5 -> 0.5 | P21: =SUM(Q21:S21)+O21 -> 22.5 | Q21: =(COUNTIF(W21:BA21,"√"))+(COUNTIF(W21:BA21,"√√")) -> 20 | R21: =COUNTIF(W21:BA21,"s") -> 1 | S21: =COUNTIF(W21:BA21,"c") -> 1 | T21: =COUNTIF(W21:BA21,"i") -> 0 | U21: =COUNTIF(W21:BA21,"") -> 3 | V21: =COUNTIF(W21:BA21,"X") -> 5 | W21: √ | X21: √ | Y21: √ | Z21: X | AA21: √ | AB21: S | AC21: √ | AD21: √ | AE21: √ | AF21: √ | AG21: X | AH21: √ | AI21: √/ | AJ21: √ | AK21: √ | AL21: √ | AM21: √ | AN21: X | AO21: √ | AP21: √ | AQ21: √ | AR21: √ | AS21: √ | AT21: X | AU21: X | AV21: C | AW21: √ | AX21: √
A22: 16 | B22: Widya Anita Saptarini | C22: Marketing | D22: =IF(KEHADIRAN!$E$7:$E$106>=2,"0",IF(KEHADIRAN!$E$7:$E$106>=1,"50%",IF(KEHADIRAN!$E$7:$E$106<=0,"100%"))) -> 100% | E22: =F21+H21 -> 1 | F22: =IF(G22:G70>=2,"0",IF(G22:G70>=1,"0",IF(G22:G70<=0,"50%"))) -> 50% | H22: =IF(I22:I70>=2,"0",IF(I22:I70>=1,"0",IF(I22:I70<=0,"50%"))) -> 50% | I22: =SUMIFS(COMPLAIN!$B$4:$B$231,COMPLAIN!$F$4:$F$231,ABSENSI!B22) -> 0 | J22: =SUMIFS(KUNJUNGAN!$C$4:$C$800,KUNJUNGAN!$B$4:$B$800,ABSENSI!$B22) -> 0 | K22: =SUMIFS(KUNJUNGAN!$J$4:$J$800,KUNJUNGAN!$B$4:$B$800,ABSENSI!$B22) -> 0 | L22: =SUMIFS(LEMBUR!$F$4:$F$235,LEMBUR!$B$4:$B$235,ABSENSI!$B22) -> 0 | M22: =COUNTIF(R22:BA22,"√√")+COUNTIF(R22:BA22,"X/") -> 0 | N22: =COUNTIF(S22:BA22,"√/") -> 0 | O22: =N22*0.5 -> 0 | P22: =SUM(Q22:S22)+O22 -> 23 | Q22: =(COUNTIF(W22:BA22,"√"))+(COUNTIF(W22:BA22,"√√")) -> 20 | R22: =COUNTIF(W22:BA22,"s") -> 0 | S22: =COUNTIF(W22:BA22,"c") -> 3 | T22: =COUNTIF(W22:BA22,"i") -> 0 | U22: =COUNTIF(W22:BA22,"") -> 3 | V22: =COUNTIF(W22:BA22,"X") -> 5 | W22: √ | X22: √ | Y22: √ | Z22: X | AA22: √ | AB22: √ | AC22: √ | AD22: √ | AE22: √ | AF22: √ | AG22: X | AH22: √ | AI22: √ | AJ22: √ | AK22: √ | AL22: √ | AM22: √ | AN22: X | AO22: √ | AP22: √ | AQ22: √ | AR22: √ | AS22: √ | AT22: X | AU22: X | AV22: C | AW22: C | AX22: C
A23: 17 | B23: Ananda Almas Saputra | C23: Teknisi Mobile | D23: =IF(KEHADIRAN!$E$7:$E$106>=2,"0",IF(KEHADIRAN!$E$7:$E$106>=1,"50%",IF(KEHADIRAN!$E$7:$E$106<=0,"100%"))) -> 100% | E23: =F23+H23 -> 1 | F23: =IF(G23:G65>=2,"0",IF(G23:G65>=1,"0",IF(G23:G65<=0,"50%"))) -> 50% | G23: =SUMIFS(GROOMING!$B$4:$B$231,GROOMING!$C$4:$C$231,ABSENSI!B23) -> 0 | H23: =IF(I23:I65>=2,"0",IF(I23:I65>=1,"0",IF(I23:I65<=0,"50%"))) -> 50% | I23: =SUMIFS(COMPLAIN!$B$4:$B$231,COMPLAIN!$F$4:$F$231,ABSENSI!B23) -> 0 | J23: =SUMIFS(KUNJUNGAN!$C$4:$C$800,KUNJUNGAN!$B$4:$B$800,ABSENSI!$B23) -> 56 | K23: =SUMIFS(KUNJUNGAN!$J$4:$J$800,KUNJUNGAN!$B$4:$B$800,ABSENSI!$B23) -> 4300 | L23: =SUMIFS(LEMBUR!$F$4:$F$235,LEMBUR!$B$4:$B$235,ABSENSI!$B23) -> 0 | M23: =COUNTIF(R23:BA23,"√√")+COUNTIF(R23:BA23,"X/") -> 0 | N23: =COUNTIF(S23:BA23,"√/") -> 0 | O23: =N23*0.5 -> 0 | P23: =SUM(Q23:S23)+O23 -> 21 | Q23: =(COUNTIF(W23:BA23,"√"))+(COUNTIF(W23:BA23,"√√")) -> 19 | R23: =COUNTIF(W23:BA23,"s") -> 0 | S23: =COUNTIF(W23:BA23,"c") -> 2 | T23: =COUNTIF(W23:BA23,"i") -> 1 | U23: =COUNTIF(W23:BA23,"") -> 3 | V23: =COUNTIF(W23:BA23,"X") -> 6 | W23: √ | X23: √ | Y23: √ | Z23: X | AA23: I | AB23: √ | AC23: √ | AD23: √ | AE23: √ | AF23: √ | AG23: X | AH23: √ | AI23: √ | AJ23: √ | AK23: √ | AL23: √ | AM23: √ | AN23: X | AO23: √ | AP23: √ | AQ23: √ | AR23: X | AS23: C | AT23: X | AU23: X | AV23: C | AW23: √ | AX23: √
A24: 18 | B24: Guruh Suseno | C24: Teknisi Station | D24: =IF(KEHADIRAN!$E$7:$E$106>=2,"0",IF(KEHADIRAN!$E$7:$E$106>=1,"50%",IF(KEHADIRAN!$E$7:$E$106<=0,"100%"))) -> 100% | E24: =F23+H23 -> 1 | F24: =IF(G24:G72>=2,"0",IF(G24:G72>=1,"0",IF(G24:G72<=0,"50%"))) -> 50% | H24: =IF(I24:I72>=2,"0",IF(I24:I72>=1,"0",IF(I24:I72<=0,"50%"))) -> 50% | I24: =SUMIFS(COMPLAIN!$B$4:$B$231,COMPLAIN!$F$4:$F$231,ABSENSI!B24) -> 0 | J24: =SUMIFS(KUNJUNGAN!$C$4:$C$800,KUNJUNGAN!$B$4:$B$800,ABSENSI!$B24) -> 0 | K24: =SUMIFS(KUNJUNGAN!$J$4:$J$800,KUNJUNGAN!$B$4:$B$800,ABSENSI!$B24) -> 0 | L24: =SUMIFS(LEMBUR!$F$4:$F$235,LEMBUR!$B$4:$B$235,ABSENSI!$B24) -> 2 | M24: =COUNTIF(R24:BA24,"√√")+COUNTIF(R24:BA24,"X/") -> 0 | N24: =COUNTIF(S24:BA24,"√/") -> 0 | O24: =N24*0.5 -> 0 | P24: =SUM(Q24:S24)+O24 -> 24 | Q24: =(COUNTIF(W24:BA24,"√"))+(COUNTIF(W24:BA24,"√√")) -> 24 | R24: =COUNTIF(W24:BA24,"s") -> 0 | S24: =COUNTIF(W24:BA24,"c") -> 0 | T24: =COUNTIF(W24:BA24,"i") -> 0 | U24: =COUNTIF(W24:BA24,"") -> 3 | V24: =COUNTIF(W24:BA24,"X") -> 4 | W24: √ | X24: √ | Y24: √ | Z24: √ | AA24: √ | AB24: √ | AC24: √ | AD24: √ | AE24: √ | AF24: X | AG24: √ | AH24: √ | AI24: X | AJ24: √ | AK24: √ | AL24: √ | AM24: X | AN24: √ | AO24: √ | AP24: √ | AQ24: √ | AR24: √ | AS24: X | AT24: √ | AU24: √ | AV24: √ | AW24: √ | AX24: √
A25: 19 | B25: Hustak Huda Ariffiandi Noor | C25: Teknisi Station | D25: =IF(KEHADIRAN!$E$7:$E$106>=2,"0",IF(KEHADIRAN!$E$7:$E$106>=1,"50%",IF(KEHADIRAN!$E$7:$E$106<=0,"100%"))) -> 100% | E25: =F25+H25 -> 1 | F25: =IF(G25:G68>=2,"0",IF(G25:G68>=1,"0",IF(G25:G68<=0,"50%"))) -> 50% | G25: =SUMIFS(GROOMING!$B$4:$B$231,GROOMING!$C$4:$C$231,ABSENSI!B25) -> 0 | H25: =IF(I25:I68>=2,"0",IF(I25:I68>=1,"0",IF(I25:I68<=0,"50%"))) -> 50% | I25: =SUMIFS(COMPLAIN!$B$4:$B$231,COMPLAIN!$F$4:$F$231,ABSENSI!B25) -> 0 | J25: =SUMIFS(KUNJUNGAN!$C$4:$C$800,KUNJUNGAN!$B$4:$B$800,ABSENSI!$B25) -> 0 | K25: =SUMIFS(KUNJUNGAN!$J$4:$J$800,KUNJUNGAN!$B$4:$B$800,ABSENSI!$B25) -> 0 | L25: =SUMIFS(LEMBUR!$F$4:$F$235,LEMBUR!$B$4:$B$235,ABSENSI!$B25) -> 1 | M25: =COUNTIF(R25:BA25,"√√")+COUNTIF(R25:BA25,"X/") -> 0 | N25: =COUNTIF(S25:BA25,"√/") -> 0 | O25: =N25*0.5 -> 0 | P25: =SUM(Q25:S25)+O25 -> 22 | Q25: =(COUNTIF(W25:BA25,"√"))+(COUNTIF(W25:BA25,"√√")) -> 22 | R25: =COUNTIF(W25:BA25,"s") -> 0 | S25: =COUNTIF(W25:BA25,"c") -> 0 | T25: =COUNTIF(W25:BA25,"i") -> 0 | U25: =COUNTIF(W25:BA25,"") -> 3 | V25: =COUNTIF(W25:BA25,"X") -> 6 | W25: √ | X25: X | Y25: √ | Z25: √ | AA25: X | AB25: √ | AC25: √ | AD25: √ | AE25: √ | AF25: √ | AG25: √ | AH25: X | AI25: √ | AJ25: √ | AK25: √ | AL25: √ | AM25: √ | AN25: √ | AO25: X | AP25: √ | AQ25: √ | AR25: √ | AS25: √ | AT25: √ | AU25: √ | AV25: X | AW25: X | AX25: √
A26: 20 | B26: Septian Dewan Putra Pratama | C26: Teknisi Station | D26: =IF(KEHADIRAN!$E$7:$E$106>=2,"0",IF(KEHADIRAN!$E$7:$E$106>=1,"50%",IF(KEHADIRAN!$E$7:$E$106<=0,"100%"))) -> 100% | E26: =F25+H25 -> 1 | F26: =IF(G26:G74>=2,"0",IF(G26:G74>=1,"0",IF(G26:G74<=0,"50%"))) -> 50% | H26: =IF(I26:I74>=2,"0",IF(I26:I74>=1,"0",IF(I26:I74<=0,"50%"))) -> 50% | I26: =SUMIFS(COMPLAIN!$B$4:$B$231,COMPLAIN!$F$4:$F$231,ABSENSI!B26) -> 0 | J26: =SUMIFS(KUNJUNGAN!$C$4:$C$800,KUNJUNGAN!$B$4:$B$800,ABSENSI!$B26) -> 0 | K26: =SUMIFS(KUNJUNGAN!$J$4:$J$800,KUNJUNGAN!$B$4:$B$800,ABSENSI!$B26) -> 0 | L26: =SUMIFS(LEMBUR!$F$4:$F$235,LEMBUR!$B$4:$B$235,ABSENSI!$B26) -> 2 | M26: =COUNTIF(R26:BA26,"√√")+COUNTIF(R26:BA26,"X/") -> 0 | N26: =COUNTIF(S26:BA26,"√/") -> 0 | O26: =N26*0.5 -> 0 | P26: =SUM(Q26:S26)+O26 -> 22 | Q26: =(COUNTIF(W26:BA26,"√"))+(COUNTIF(W26:BA26,"√√")) -> 21 | R26: =COUNTIF(W26:BA26,"s") -> 1 | S26: =COUNTIF(W26:BA26,"c") -> 0 | T26: =COUNTIF(W26:BA26,"i") -> 1 | U26: =COUNTIF(W26:BA26,"") -> 3 | V26: =COUNTIF(W26:BA26,"X") -> 5 | W26: X | X26: √ | Y26: √ | Z26: √ | AA26: I | AB26: √ | AC26: √ | AD26: √ | AE26: X | AF26: √ | AG26: √ | AH26: X | AI26: √ | AJ26: √ | AK26: √ | AL26: √ | AM26: √ | AN26: S | AO26: √ | AP26: √ | AQ26: √ | AR26: √ | AS26: √ | AT26: X | AU26: X | AV26: √ | AW26: √ | AX26: √
A27: 21 | B27: Alim Wijaya | C27: Teknisi Station | D27: =IF(KEHADIRAN!$E$7:$E$106>=2,"0",IF(KEHADIRAN!$E$7:$E$106>=1,"50%",IF(KEHADIRAN!$E$7:$E$106<=0,"100%"))) -> 100% | E27: =F27+H27 -> 1 | F27: =IF(G27:G70>=2,"0",IF(G27:G70>=1,"0",IF(G27:G70<=0,"50%"))) -> 50% | G27: =SUMIFS(GROOMING!$B$4:$B$231,GROOMING!$C$4:$C$231,ABSENSI!B27) -> 0 | H27: =IF(I27:I70>=2,"0",IF(I27:I70>=1,"0",IF(I27:I70<=0,"50%"))) -> 50% | I27: =SUMIFS(COMPLAIN!$B$4:$B$231,COMPLAIN!$F$4:$F$231,ABSENSI!B27) -> 0 | J27: =SUMIFS(KUNJUNGAN!$C$4:$C$800,KUNJUNGAN!$B$4:$B$800,ABSENSI!$B27) -> 0 | K27: =SUMIFS(KUNJUNGAN!$J$4:$J$800,KUNJUNGAN!$B$4:$B$800,ABSENSI!$B27) -> 0 | L27: =SUMIFS(LEMBUR!$F$4:$F$235,LEMBUR!$B$4:$B$235,ABSENSI!$B27) -> 0 | M27: =COUNTIF(R27:BA27,"√√")+COUNTIF(R27:BA27,"X/") -> 0 | N27: =COUNTIF(S27:BA27,"√/") -> 0 | O27: =N27*0.5 -> 0 | P27: =SUM(Q27:S27)+O27 -> 23 | Q27: =(COUNTIF(W27:BA27,"√"))+(COUNTIF(W27:BA27,"√√")) -> 22 | R27: =COUNTIF(W27:BA27,"s") -> 0 | S27: =COUNTIF(W27:BA27,"c") -> 1 | T27: =COUNTIF(W27:BA27,"i") -> 0 | U27: =COUNTIF(W27:BA27,"") -> 3 | V27: =COUNTIF(W27:BA27,"X") -> 5 | W27: √ | X27: √ | Y27: X | Z27: X | AA27: √ | AB27: √ | AC27: √ | AD27: √ | AE27: √ | AF27: √ | AG27: X | AH27: √ | AI27: √ | AJ27: √ | AK27: √ | AL27: √ | AM27: √ | AN27: X | AO27: C | AP27: √ | AQ27: √ | AR27: √ | AS27: √ | AT27: √ | AU27: √ | AV27: √ | AW27: X | AX27: √
A28: 22 | B28: I Wayan Rendy Tirta Ardana | C28: Teknisi Support | D28: =IF(KEHADIRAN!$E$7:$E$106>=2,"0",IF(KEHADIRAN!$E$7:$E$106>=1,"50%",IF(KEHADIRAN!$E$7:$E$106<=0,"100%"))) -> 100% | E28: =F27+H27 -> 1 | F28: =IF(G28:G76>=2,"0",IF(G28:G76>=1,"0",IF(G28:G76<=0,"50%"))) -> 50% | H28: =IF(I28:I76>=2,"0",IF(I28:I76>=1,"0",IF(I28:I76<=0,"50%"))) -> 50% | I28: =SUMIFS(COMPLAIN!$B$4:$B$231,COMPLAIN!$F$4:$F$231,ABSENSI!B28) -> 0 | J28: =SUMIFS(KUNJUNGAN!$C$4:$C$800,KUNJUNGAN!$B$4:$B$800,ABSENSI!$B28) -> 0 | K28: =SUMIFS(KUNJUNGAN!$J$4:$J$800,KUNJUNGAN!$B$4:$B$800,ABSENSI!$B28) -> 0 | L28: =SUMIFS(LEMBUR!$F$4:$F$235,LEMBUR!$B$4:$B$235,ABSENSI!$B28) -> 5.5 | M28: =COUNTIF(R28:BA28,"√√")+COUNTIF(R28:BA28,"X/") -> 0 | N28: =COUNTIF(S28:BA28,"√/") -> 0 | O28: =N28*0.5 -> 0 | P28: =SUM(Q28:S28)+O28 -> 21 | Q28: =(COUNTIF(W28:BA28,"√"))+(COUNTIF(W28:BA28,"√√")) -> 18 | R28: =COUNTIF(W28:BA28,"s") -> 1 | S28: =COUNTIF(W28:BA28,"c") -> 2 | T28: =COUNTIF(W28:BA28,"i") -> 1 | U28: =COUNTIF(W28:BA28,"") -> 3 | V28: =COUNTIF(W28:BA28,"X") -> 6 | W28: C | X28: X | Y28: C | Z28: X | AA28: √ | AB28: √ | AC28: √ | AD28: √ | AE28: √ | AF28: X | AG28: I | AH28: S | AI28: √ | AJ28: √ | AK28: √ | AL28: √ | AM28: X | AN28: √ | AO28: √ | AP28: √ | AQ28: √ | AR28: √ | AS28: √ | AT28: X | AU28: X | AV28: √ | AW28: √ | AX28: √
A29: 23 | B29: Dwi Yulianto | C29: Teknisi Station | D29: =IF(KEHADIRAN!$E$7:$E$106>=2,"0",IF(KEHADIRAN!$E$7:$E$106>=1,"50%",IF(KEHADIRAN!$E$7:$E$106<=0,"100%"))) -> 100% | E29: =F29+H29 -> 1 | F29: =IF(G29:G72>=2,"0",IF(G29:G72>=1,"0",IF(G29:G72<=0,"50%"))) -> 50% | G29: =SUMIFS(GROOMING!$B$4:$B$231,GROOMING!$C$4:$C$231,ABSENSI!B29) -> 0 | H29: =IF(I29:I72>=2,"0",IF(I29:I72>=1,"0",IF(I29:I72<=0,"50%"))) -> 50% | I29: =SUMIFS(COMPLAIN!$B$4:$B$231,COMPLAIN!$F$4:$F$231,ABSENSI!B29) -> 0 | J29: =SUMIFS(KUNJUNGAN!$C$4:$C$800,KUNJUNGAN!$B$4:$B$800,ABSENSI!$B29) -> 0 | K29: =SUMIFS(KUNJUNGAN!$J$4:$J$800,KUNJUNGAN!$B$4:$B$800,ABSENSI!$B29) -> 0 | L29: =SUMIFS(LEMBUR!$F$4:$F$235,LEMBUR!$B$4:$B$235,ABSENSI!$B29) -> 1 | M29: =COUNTIF(R29:BA29,"√√")+COUNTIF(R29:BA29,"X/") -> 0 | N29: =COUNTIF(S29:BA29,"√/") -> 0 | O29: =N29*0.5 -> 0 | P29: =SUM(Q29:S29)+O29 -> 22 | Q29: =(COUNTIF(W29:BA29,"√"))+(COUNTIF(W29:BA29,"√√")) -> 21 | R29: =COUNTIF(W29:BA29,"s") -> 0 | S29: =COUNTIF(W29:BA29,"c") -> 1 | T29: =COUNTIF(W29:BA29,"i") -> 0 | U29: =COUNTIF(W29:BA29,"") -> 3 | V29: =COUNTIF(W29:BA29,"X") -> 6 | W29: C | X29: √ | Y29: √ | Z29: √ | AA29: √ | AB29: X | AC29: √ | AD29: √ | AE29: √ | AF29: √ | AG29: √ | AH29: √ | AI29: X | AJ29: √ | AK29: √ | AL29: X | AM29: √ | AN29: √ | AO29: √ | AP29: X | AQ29: √ | AR29: X | AS29: X | AT29: √ | AU29: √ | AV29: √ | AW29: √ | AX29: √
A30: 24 | B30: Dwi Santoso | C30: Teknisi Station | D30: =IF(KEHADIRAN!$E$7:$E$106>=2,"0",IF(KEHADIRAN!$E$7:$E$106>=1,"50%",IF(KEHADIRAN!$E$7:$E$106<=0,"100%"))) -> 100% | E30: =F29+H29 -> 1 | F30: =IF(G30:G78>=2,"0",IF(G30:G78>=1,"0",IF(G30:G78<=0,"50%"))) -> 50% | H30: =IF(I30:I78>=2,"0",IF(I30:I78>=1,"0",IF(I30:I78<=0,"50%"))) -> 50% | I30: =SUMIFS(COMPLAIN!$B$4:$B$231,COMPLAIN!$F$4:$F$231,ABSENSI!B30) -> 0 | J30: =SUMIFS(KUNJUNGAN!$C$4:$C$800,KUNJUNGAN!$B$4:$B$800,ABSENSI!$B30) -> 0 | K30: =SUMIFS(KUNJUNGAN!$J$4:$J$800,KUNJUNGAN!$B$4:$B$800,ABSENSI!$B30) -> 0 | L30: =SUMIFS(LEMBUR!$F$4:$F$235,LEMBUR!$B$4:$B$235,ABSENSI!$B30) -> 0 | M30: =COUNTIF(R30:BA30,"√√")+COUNTIF(R30:BA30,"X/") -> 0 | N30: =COUNTIF(S30:BA30,"√/") -> 0 | O30: =N30*0.5 -> 0 | P30: =SUM(Q30:S30)+O30 -> 24 | Q30: =(COUNTIF(W30:BA30,"√"))+(COUNTIF(W30:BA30,"√√")) -> 24 | R30: =COUNTIF(W30:BA30,"s") -> 0 | S30: =COUNTIF(W30:BA30,"c") -> 0 | T30: =COUNTIF(W30:BA30,"i") -> 0 | U30: =COUNTIF(W30:BA30,"") -> 3 | V30: =COUNTIF(W30:BA30,"X") -> 4 | W30: √ | X30: √ | Y30: √ | Z30: √ | AA30: √ | AB30: X | AC30: √ | AD30: √ | AE30: √ | AF30: √ | AG30: √ | AH30: √ | AI30: X | AJ30: √ | AK30: √ | AL30: √ | AM30: √ | AN30: √ | AO30: √ | AP30: X | AQ30: √ | AR30: √ | AS30: √ | AT30: √ | AU30: √ | AV30: √ | AW30: √ | AX30: X
A31: 25 | B31: Fandi Aprilianto | C31: GA | D31: =IF(KEHADIRAN!$E$7:$E$106>=2,"0",IF(KEHADIRAN!$E$7:$E$106>=1,"50%",IF(KEHADIRAN!$E$7:$E$106<=0,"100%"))) -> 100% | E31: =F31+H31 -> 1 | F31: =IF(G31:G74>=2,"0",IF(G31:G74>=1,"0",IF(G31:G74<=0,"50%"))) -> 50% | G31: =SUMIFS(GROOMING!$B$4:$B$231,GROOMING!$C$4:$C$231,ABSENSI!B31) -> 0 | H31: =IF(I31:I74>=2,"0",IF(I31:I74>=1,"0",IF(I31:I74<=0,"50%"))) -> 50% | I31: =SUMIFS(COMPLAIN!$B$4:$B$231,COMPLAIN!$F$4:$F$231,ABSENSI!B31) -> 0 | J31: =SUMIFS(KUNJUNGAN!$C$4:$C$800,KUNJUNGAN!$B$4:$B$800,ABSENSI!$B31) -> 0 | K31: =SUMIFS(KUNJUNGAN!$J$4:$J$800,KUNJUNGAN!$B$4:$B$800,ABSENSI!$B31) -> 0 | L31: =SUMIFS(LEMBUR!$F$4:$F$235,LEMBUR!$B$4:$B$235,ABSENSI!$B31) -> 34 | M31: =COUNTIF(R31:BA31,"√√")+COUNTIF(R31:BA31,"X/") -> 0 | N31: =COUNTIF(S31:BA31,"√/") -> 0 | O31: =N31*0.5 -> 0 | P31: =SUM(Q31:S31)+O31 -> 24 | Q31: =(COUNTIF(W31:BA31,"√"))+(COUNTIF(W31:BA31,"√√")) -> 21 | R31: =COUNTIF(W31:BA31,"s") -> 0 | S31: =COUNTIF(W31:BA31,"c") -> 3 | T31: =COUNTIF(W31:BA31,"i") -> 0 | U31: =COUNTIF(W31:BA31,"") -> 3 | V31: =COUNTIF(W31:BA31,"X") -> 4 | W31: √ | X31: √ | Y31: √ | Z31: X | AA31: √ | AB31: √ | AC31: √ | AD31: √ | AE31: √ | AF31: √ | AG31: X | AH31: √ | AI31: √ | AJ31: √ | AK31: √ | AL31: √ | AM31: √ | AN31: √ | AO31: √ | AP31: √ | AQ31: √ | AR31: √ | AS31: √ | AT31: X | AU31: X | AV31: C | AW31: C | AX31: C
A32: 26 | B32: Adam Abdillah | C32: Teknisi Mobile | D32: =IF(KEHADIRAN!$E$7:$E$106>=2,"0",IF(KEHADIRAN!$E$7:$E$106>=1,"50%",IF(KEHADIRAN!$E$7:$E$106<=0,"100%"))) -> 100% | E32: =F31+H31 -> 1 | F32: =IF(G32:G80>=2,"0",IF(G32:G80>=1,"0",IF(G32:G80<=0,"50%"))) -> 50% | H32: =IF(I32:I80>=2,"0",IF(I32:I80>=1,"0",IF(I32:I80<=0,"50%"))) -> 50% | I32: =SUMIFS(COMPLAIN!$B$4:$B$231,COMPLAIN!$F$4:$F$231,ABSENSI!B32) -> 0 | J32: =SUMIFS(KUNJUNGAN!$C$4:$C$800,KUNJUNGAN!$B$4:$B$800,ABSENSI!$B32) -> 60 | K32: =SUMIFS(KUNJUNGAN!$J$4:$J$800,KUNJUNGAN!$B$4:$B$800,ABSENSI!$B32) -> 7589 | L32: =SUMIFS(LEMBUR!$F$4:$F$235,LEMBUR!$B$4:$B$235,ABSENSI!$B32) -> 0 | M32: =COUNTIF(R32:BA32,"√√")+COUNTIF(R32:BA32,"X/") -> 0 | N32: =COUNTIF(S32:BA32,"√/") -> 0 | O32: =N32*0.5 -> 0 | P32: =SUM(Q32:S32)+O32 -> 22 | Q32: =(COUNTIF(W32:BA32,"√"))+(COUNTIF(W32:BA32,"√√")) -> 21 | R32: =COUNTIF(W32:BA32,"s") -> 0 | S32: =COUNTIF(W32:BA32,"c") -> 1 | T32: =COUNTIF(W32:BA32,"i") -> 0 | U32: =COUNTIF(W32:BA32,"") -> 3 | V32: =COUNTIF(W32:BA32,"X") -> 6 | W32: √ | X32: √ | Y32: √ | Z32: X | AA32: √ | AB32: √ | AC32: √ | AD32: √ | AE32: √ | AF32: √ | AG32: X | AH32: √ | AI32: √ | AJ32: √ | AK32: √ | AL32: √ | AM32: √ | AN32: X | AO32: √ | AP32: √ | AQ32: √ | AR32: X | AS32: √ | AT32: X | AU32: X | AV32: C | AW32: √ | AX32: √
A33: 27 | B33: Setyo Nugroho Panji Ramadhan | C33: Teknisi Station | D33: =IF(KEHADIRAN!$E$7:$E$106>=2,"0",IF(KEHADIRAN!$E$7:$E$106>=1,"50%",IF(KEHADIRAN!$E$7:$E$106<=0,"100%"))) -> 100% | E33: =F33+H33 -> 1 | F33: =IF(G33:G76>=2,"0",IF(G33:G76>=1,"0",IF(G33:G76<=0,"50%"))) -> 50% | G33: =SUMIFS(GROOMING!$B$4:$B$231,GROOMING!$C$4:$C$231,ABSENSI!B33) -> 0 | H33: =IF(I33:I76>=2,"0",IF(I33:I76>=1,"0",IF(I33:I76<=0,"50%"))) -> 50% | I33: =SUMIFS(COMPLAIN!$B$4:$B$231,COMPLAIN!$F$4:$F$231,ABSENSI!B33) -> 0 | J33: =SUMIFS(KUNJUNGAN!$C$4:$C$800,KUNJUNGAN!$B$4:$B$800,ABSENSI!$B33) -> 0 | K33: =SUMIFS(KUNJUNGAN!$J$4:$J$800,KUNJUNGAN!$B$4:$B$800,ABSENSI!$B33) -> 0 | L33: =SUMIFS(LEMBUR!$F$4:$F$235,LEMBUR!$B$4:$B$235,ABSENSI!$B33) -> 1 | M33: =COUNTIF(R33:BA33,"√√")+COUNTIF(R33:BA33,"X/") -> 0 | N33: =COUNTIF(S33:BA33,"√/") -> 0 | O33: =N33*0.5 -> 0 | P33: =SUM(Q33:S33)+O33 -> 23 | Q33: =(COUNTIF(W33:BA33,"√"))+(COUNTIF(W33:BA33,"√√")) -> 23 | R33: =COUNTIF(W33:BA33,"s") -> 0 | S33: =COUNTIF(W33:BA33,"c") -> 0 | T33: =COUNTIF(W33:BA33,"i") -> 0 | U33: =COUNTIF(W33:BA33,"") -> 3 | V33: =COUNTIF(W33:BA33,"X") -> 5 | W33: √ | X33: √ | Y33: √ | Z33: X | AA33: √ | AB33: √ | AC33: √ | AD33: √ | AE33: √ | AF33: √ | AG33: X | AH33: √ | AI33: √ | AJ33: √ | AK33: √ | AL33: √ | AM33: √ | AN33: X | AO33: √ | AP33: √ | AQ33: √ | AR33: X | AS33: √ | AT33: √ | AU33: X | AV33: √ | AW33: √ | AX33: √
A34: 28 | B34: Rizal Darmawan | C34: Teknisi Station | D34: =IF(KEHADIRAN!$E$7:$E$106>=2,"0",IF(KEHADIRAN!$E$7:$E$106>=1,"50%",IF(KEHADIRAN!$E$7:$E$106<=0,"100%"))) -> 100% | E34: =F33+H33 -> 1 | F34: =IF(G34:G82>=2,"0",IF(G34:G82>=1,"0",IF(G34:G82<=0,"50%"))) -> 50% | H34: =IF(I34:I82>=2,"0",IF(I34:I82>=1,"0",IF(I34:I82<=0,"50%"))) -> 50% | I34: =SUMIFS(COMPLAIN!$B$4:$B$231,COMPLAIN!$F$4:$F$231,ABSENSI!B34) -> 0 | J34: =SUMIFS(KUNJUNGAN!$C$4:$C$800,KUNJUNGAN!$B$4:$B$800,ABSENSI!$B34) -> 0 | K34: =SUMIFS(KUNJUNGAN!$J$4:$J$800,KUNJUNGAN!$B$4:$B$800,ABSENSI!$B34) -> 0 | L34: =SUMIFS(LEMBUR!$F$4:$F$235,LEMBUR!$B$4:$B$235,ABSENSI!$B34) -> 0 | M34: =COUNTIF(R34:BA34,"√√")+COUNTIF(R34:BA34,"X/") -> 0 | N34: =COUNTIF(S34:BA34,"√/") -> 0 | O34: =N34*0.5 -> 0 | P34: =SUM(Q34:S34)+O34 -> 22 | Q34: =(COUNTIF(W34:BA34,"√"))+(COUNTIF(W34:BA34,"√√")) -> 21 | R34: =COUNTIF(W34:BA34,"s") -> 0 | S34: =COUNTIF(W34:BA34,"c") -> 1 | T34: =COUNTIF(W34:BA34,"i") -> 1 | U34: =COUNTIF(W34:BA34,"") -> 3 | V34: =COUNTIF(W34:BA34,"X") -> 5 | W34: I | X34: √ | Y34: √ | Z34: X | AA34: √ | AB34: √ | AC34: √ | AD34: √ | AE34: √ | AF34: √ | AG34: X | AH34: √ | AI34: √ | AJ34: √ | AK34: √ | AL34: √ | AM34: C | AN34: X | AO34: √ | AP34: √ | AQ34: √ | AR34: √ | AS34: √ | AT34: X | AU34: X | AV34: √ | AW34: √ | AX34: √
A35: 29 | B35: Ekan Novi Pangestu | C35: Marketing | D35: =IF(KEHADIRAN!$E$7:$E$106>=2,"0",IF(KEHADIRAN!$E$7:$E$106>=1,"50%",IF(KEHADIRAN!$E$7:$E$106<=0,"100%"))) -> 100% | E35: =F35+H35 -> 1 | F35: =IF(G35:G78>=2,"0",IF(G35:G78>=1,"0",IF(G35:G78<=0,"50%"))) -> 50% | G35: =SUMIFS(GROOMING!$B$4:$B$231,GROOMING!$C$4:$C$231,ABSENSI!B35) -> 0 | H35: =IF(I35:I78>=2,"0",IF(I35:I78>=1,"0",IF(I35:I78<=0,"50%"))) -> 50% | I35: =SUMIFS(COMPLAIN!$B$4:$B$231,COMPLAIN!$F$4:$F$231,ABSENSI!B35) -> 0 | J35: =SUMIFS(KUNJUNGAN!$C$4:$C$800,KUNJUNGAN!$B$4:$B$800,ABSENSI!$B35) -> 0 | K35: =SUMIFS(KUNJUNGAN!$J$4:$J$800,KUNJUNGAN!$B$4:$B$800,ABSENSI!$B35) -> 0 | L35: =SUMIFS(LEMBUR!$F$4:$F$235,LEMBUR!$B$4:$B$235,ABSENSI!$B35) -> 0 | M35: =COUNTIF(R35:BA35,"√√")+COUNTIF(R35:BA35,"X/") -> 0 | N35: =COUNTIF(S35:BA35,"√/") -> 0 | O35: =N35*0.5 -> 0 | P35: =SUM(Q35:S35)+O35 -> 22 | Q35: =(COUNTIF(W35:BA35,"√"))+(COUNTIF(W35:BA35,"√√")) -> 18 | R35: =COUNTIF(W35:BA35,"s") -> 0 | S35: =COUNTIF(W35:BA35,"c") -> 4 | T35: =COUNTIF(W35:BA35,"i") -> 0 | U35: =COUNTIF(W35:BA35,"") -> 3 | V35: =COUNTIF(W35:BA35,"X") -> 6 | W35: √ | X35: √ | Y35: √ | Z35: X | AA35: √ | AB35: √ | AC35: √ | AD35: √ | AE35: √ | AF35: √ | AG35: X | AH35: √ | AI35: √ | AJ35: √ | AK35: √ | AL35: √ | AM35: √ | AN35: X | AO35: √ | AP35: √ | AQ35: √ | AR35: X | AS35: C | AT35: X | AU35: X | AV35: C | AW35: C | AX35: C
A36: 30 | B36: Argantara Alif Saputra | C36: Teknisi Station | D36: 100% | E36: 1 | F36: 50% | G36: 0 | H36: 50% | I36: =SUMIFS(COMPLAIN!$B$4:$B$231,COMPLAIN!$F$4:$F$231,ABSENSI!B36) -> 0 | J36: =SUMIFS(KUNJUNGAN!$C$4:$C$800,KUNJUNGAN!$B$4:$B$800,ABSENSI!$B36) -> 0 | K36: =SUMIFS(KUNJUNGAN!$J$4:$J$800,KUNJUNGAN!$B$4:$B$800,ABSENSI!$B36) -> 0 | L36: =SUMIFS(LEMBUR!$F$4:$F$235,LEMBUR!$B$4:$B$235,ABSENSI!$B36) -> 28 | M36: =COUNTIF(R36:BA36,"√√")+COUNTIF(R36:BA36,"X/") -> 0 | N36: =COUNTIF(S36:BA36,"√/") -> 0 | O36: =N36*0.5 -> 0 | P36: =SUM(Q36:S36)+O36 -> 22 | Q36: =(COUNTIF(W36:BA36,"√"))+(COUNTIF(W36:BA36,"√√")) -> 21 | R36: =COUNTIF(W36:BA36,"s") -> 0 | S36: =COUNTIF(W36:BA36,"c") -> 1 | T36: =COUNTIF(W36:BA36,"i") -> 0 | U36: =COUNTIF(W36:BA36,"") -> 3 | V36: =COUNTIF(W36:BA36,"X") -> 6 | W36: C | X36: √ | Y36: √ | Z36: √ | AA36: √ | AB36: √ | AC36: √ | AD36: √ | AE36: √ | AF36: √ | AG36: √ | AH36: √ | AI36: √ | AJ36: X | AK36: √ | AL36: √ | AM36: √ | AN36: √ | AO36: √ | AP36: √ | AQ36: X | AR36: X | AS36: X | AT36: X | AU36: X | AV36: √ | AW36: √ | AX36: √
A37: 31 | B37: Moch Maulana | C37: Teknisi Support | D37: 100% | E37: 1 | F37: 50% | H37: 50% | I37: =SUMIFS(COMPLAIN!$B$4:$B$231,COMPLAIN!$F$4:$F$231,ABSENSI!B37) -> 0 | J37: =SUMIFS(KUNJUNGAN!$C$4:$C$800,KUNJUNGAN!$B$4:$B$800,ABSENSI!$B37) -> 0 | K37: =SUMIFS(KUNJUNGAN!$J$4:$J$800,KUNJUNGAN!$B$4:$B$800,ABSENSI!$B37) -> 0 | L37: =SUMIFS(LEMBUR!$F$4:$F$235,LEMBUR!$B$4:$B$235,ABSENSI!$B37) -> 0 | M37: =COUNTIF(R37:BA37,"√√")+COUNTIF(R37:BA37,"X/") -> 0 | N37: =COUNTIF(S37:BA37,"√/") -> 0 | O37: =N37*0.5 -> 0 | P37: =SUM(Q37:S37)+O37 -> 23 | Q37: =(COUNTIF(W37:BA37,"√"))+(COUNTIF(W37:BA37,"√√")) -> 21 | R37: =COUNTIF(W37:BA37,"s") -> 0 | S37: =COUNTIF(W37:BA37,"c") -> 2 | T37: =COUNTIF(W37:BA37,"i") -> 0 | U37: =COUNTIF(W37:BA37,"") -> 3 | V37: =COUNTIF(W37:BA37,"X") -> 5 | W37: √ | X37: √ | Y37: √ | Z37: X | AA37: √ | AB37: √ | AC37: √ | AD37: √ | AE37: √ | AF37: √ | AG37: X | AH37: √ | AI37: √ | AJ37: √ | AK37: √ | AL37: √ | AM37: √ | AN37: X | AO37: √ | AP37: √ | AQ37: √ | AR37: √ | AS37: C | AT37: X | AU37: X | AV37: C | AW37: √ | AX37: √
A38: 32 | B38: Aldimas Fachrur Rozi | C38: Teknisi Station | D38: 100% | E38: 1 | F38: 50% | G38: 0 | H38: 50% | I38: =SUMIFS(COMPLAIN!$B$4:$B$231,COMPLAIN!$F$4:$F$231,ABSENSI!B38) -> 0 | J38: =SUMIFS(KUNJUNGAN!$C$4:$C$800,KUNJUNGAN!$B$4:$B$800,ABSENSI!$B38) -> 0 | K38: =SUMIFS(KUNJUNGAN!$J$4:$J$800,KUNJUNGAN!$B$4:$B$800,ABSENSI!$B38) -> 0 | L38: =SUMIFS(LEMBUR!$F$4:$F$235,LEMBUR!$B$4:$B$235,ABSENSI!$B38) -> 0 | M38: =COUNTIF(R38:BA38,"√√")+COUNTIF(R38:BA38,"X/") -> 0 | N38: =COUNTIF(S38:BA38,"√/") -> 0 | O38: =N38*0.5 -> 0 | P38: =SUM(Q38:S38)+O38 -> 22 | Q38: =(COUNTIF(W38:BA38,"√"))+(COUNTIF(W38:BA38,"√√")) -> 21 | R38: =COUNTIF(W38:BA38,"s") -> 1 | S38: =COUNTIF(W38:BA38,"c") -> 0 | T38: =COUNTIF(W38:BA38,"i") -> 0 | U38: =COUNTIF(W38:BA38,"") -> 3 | V38: =COUNTIF(W38:BA38,"X") -> 6 | W38: √ | X38: √ | Y38: √ | Z38: √ | AA38: √ | AB38: √ | AC38: X | AD38: √ | AE38: √ | AF38: √ | AG38: √ | AH38: √ | AI38: √ | AJ38: X | AK38: √ | AL38: √ | AM38: √ | AN38: √ | AO38: S | AP38: √ | AQ38: X | AR38: √ | AS38: X | AT38: X | AU38: √ | AV38: √ | AW38: √ | AX38: X
A39: 33 | B39: Asrori Rusdy | C39: Driver | D39: 100% | E39: 1 | F39: 50% | H39: 50% | I39: =SUMIFS(COMPLAIN!$B$4:$B$231,COMPLAIN!$F$4:$F$231,ABSENSI!B39) -> 0 | J39: =SUMIFS(KUNJUNGAN!$C$4:$C$800,KUNJUNGAN!$B$4:$B$800,ABSENSI!$B39) -> 0 | K39: =SUMIFS(KUNJUNGAN!$J$4:$J$800,KUNJUNGAN!$B$4:$B$800,ABSENSI!$B39) -> 0 | L39: =SUMIFS(LEMBUR!$F$4:$F$235,LEMBUR!$B$4:$B$235,ABSENSI!$B39) -> 45 | M39: =COUNTIF(R39:BA39,"√√")+COUNTIF(R39:BA39,"X/") -> 1 | N39: =COUNTIF(S39:BA39,"√/") -> 0 | O39: =N39*0.5 -> 0 | P39: =SUM(Q39:S39)+O39 -> 22 | Q39: =(COUNTIF(W39:BA39,"√"))+(COUNTIF(W39:BA39,"√√")) -> 20 | R39: =COUNTIF(W39:BA39,"s") -> 0 | S39: =COUNTIF(W39:BA39,"c") -> 2 | T39: =COUNTIF(W39:BA39,"i") -> 1 | U39: =COUNTIF(W39:BA39,"") -> 3 | V39: =COUNTIF(W39:BA39,"X") -> 5 | W39: √ | X39: √ | Y39: √ | Z39: X | AA39: √ | AB39: √ | AC39: √ | AD39: √ | AE39: √ | AF39: √ | AG39: √√ | AH39: √ | AI39: √ | AJ39: √ | AK39: √ | AL39: I | AM39: √ | AN39: X | AO39: √ | AP39: √ | AQ39: √ | AR39: X | AS39: √ | AT39: X | AU39: X | AV39: C | AW39: C | AX39: √
A40: 34 | B40: Mauliddina Althaf Amanda | C40: Admin Operasional | D40: 100% | E40: 1 | F40: 50% | G40: 0 | H40: 50% | I40: =SUMIFS(COMPLAIN!$B$4:$B$231,COMPLAIN!$F$4:$F$231,ABSENSI!B40) -> 0 | J40: =SUMIFS(KUNJUNGAN!$C$4:$C$800,KUNJUNGAN!$B$4:$B$800,ABSENSI!$B40) -> 0 | K40: =SUMIFS(KUNJUNGAN!$J$4:$J$800,KUNJUNGAN!$B$4:$B$800,ABSENSI!$B40) -> 0 | L40: =SUMIFS(LEMBUR!$F$4:$F$235,LEMBUR!$B$4:$B$235,ABSENSI!$B40) -> 0 | M40: =COUNTIF(R40:BA40,"√√")+COUNTIF(R40:BA40,"X/") -> 0 | N40: =COUNTIF(S40:BA40,"√/") -> 0 | O40: =N40*0.5 -> 0 | P40: =SUM(Q40:S40)+O40 -> 20 | Q40: =(COUNTIF(W40:BA40,"√"))+(COUNTIF(W40:BA40,"√√")) -> 18 | R40: =COUNTIF(W40:BA40,"s") -> 0 | S40: =COUNTIF(W40:BA40,"c") -> 2 | T40: =COUNTIF(W40:BA40,"i") -> 2 | U40: =COUNTIF(W40:BA40,"") -> 3 | V40: =COUNTIF(W40:BA40,"X") -> 6 | W40: √ | X40: √ | Y40: √ | Z40: X | AA40: √ | AB40: √ | AC40: √ | AD40: √ | AE40: I | AF40: √ | AG40: X | AH40: √ | AI40: √ | AJ40: √ | AK40: √ | AL40: √ | AM40: √ | AN40: X | AO40: √ | AP40: √ | AQ40: √ | AR40: X | AS40: I | AT40: X | AU40: X | AV40: C | AW40: C | AX40: √
A41: 35 | B41: Bustomi | C41: Teknisi Station | D41: 100% | E41: 1 | F41: 50% | H41: 50% | I41: =SUMIFS(COMPLAIN!$B$4:$B$231,COMPLAIN!$F$4:$F$231,ABSENSI!B41) -> 0 | J41: =SUMIFS(KUNJUNGAN!$C$4:$C$800,KUNJUNGAN!$B$4:$B$800,ABSENSI!$B41) -> 0 | K41: =SUMIFS(KUNJUNGAN!$J$4:$J$800,KUNJUNGAN!$B$4:$B$800,ABSENSI!$B41) -> 0 | L41: =SUMIFS(LEMBUR!$F$4:$F$235,LEMBUR!$B$4:$B$235,ABSENSI!$B41) -> 0 | M41: =COUNTIF(R41:BA41,"√√")+COUNTIF(R41:BA41,"X/") -> 0 | N41: =COUNTIF(S41:BA41,"√/") -> 0 | O41: =N41*0.5 -> 0 | P41: =SUM(Q41:S41)+O41 -> 21 | Q41: =(COUNTIF(W41:BA41,"√"))+(COUNTIF(W41:BA41,"√√")) -> 21 | R41: =COUNTIF(W41:BA41,"s") -> 0 | S41: =COUNTIF(W41:BA41,"c") -> 0 | T41: =COUNTIF(W41:BA41,"i") -> 1 | U41: =COUNTIF(W41:BA41,"") -> 3 | V41: =COUNTIF(W41:BA41,"X") -> 6 | W41: √ | X41: X | Y41: √ | Z41: √ | AA41: √ | AB41: √ | AC41: X | AD41: √ | AE41: √ | AF41: √ | AG41: I | AH41: √ | AI41: √ | AJ41: X | AK41: √ | AL41: √ | AM41: √ | AN41: √ | AO41: √ | AP41: √ | AQ41: X | AR41: √ | AS41: √ | AT41: √ | AU41: √ | AV41: √ | AW41: X | AX41: X
A42: 36 | B42: Mohammad Firman | C42: Teknisi Station | D42: 100% | E42: 1 | F42: 50% | G42: 0 | H42: 50% | I42: =SUMIFS(COMPLAIN!$B$4:$B$231,COMPLAIN!$F$4:$F$231,ABSENSI!B42) -> 0 | J42: =SUMIFS(KUNJUNGAN!$C$4:$C$800,KUNJUNGAN!$B$4:$B$800,ABSENSI!$B42) -> 0 | K42: =SUMIFS(KUNJUNGAN!$J$4:$J$800,KUNJUNGAN!$B$4:$B$800,ABSENSI!$B42) -> 0 | L42: =SUMIFS(LEMBUR!$F$4:$F$235,LEMBUR!$B$4:$B$235,ABSENSI!$B42) -> 0 | M42: =COUNTIF(R42:BA42,"√√")+COUNTIF(R42:BA42,"X/") -> 0 | N42: =COUNTIF(S42:BA42,"√/") -> 0 | O42: =N42*0.5 -> 0 | P42: =SUM(Q42:S42)+O42 -> 25 | Q42: =(COUNTIF(W42:BA42,"√"))+(COUNTIF(W42:BA42,"√√")) -> 24 | R42: =COUNTIF(W42:BA42,"s") -> 0 | S42: =COUNTIF(W42:BA42,"c") -> 1 | T42: =COUNTIF(W42:BA42,"i") -> 0 | U42: =COUNTIF(W42:BA42,"") -> 3 | V42: =COUNTIF(W42:BA42,"X") -> 3 | W42: C | X42: √ | Y42: √ | Z42: √ | AA42: √ | AB42: √ | AC42: √ | AD42: √ | AE42: √ | AF42: X | AG42: √ | AH42: √ | AI42: √ | AJ42: √ | AK42: √ | AL42: √ | AM42: X | AN42: √ | AO42: √ | AP42: √ | AQ42: X | AR42: √ | AS42: √ | AT42: √ | AU42: √ | AV42: √ | AW42: √ | AX42: √
A43: 37 | B43: Farchan Adi Saputro | C43: Teknisi Station | D43: 100% | E43: 1 | F43: 50% | H43: 50% | I43: =SUMIFS(COMPLAIN!$B$4:$B$231,COMPLAIN!$F$4:$F$231,ABSENSI!B43) -> 0 | J43: =SUMIFS(KUNJUNGAN!$C$4:$C$800,KUNJUNGAN!$B$4:$B$800,ABSENSI!$B43) -> 0 | K43: =SUMIFS(KUNJUNGAN!$J$4:$J$800,KUNJUNGAN!$B$4:$B$800,ABSENSI!$B43) -> 0 | L43: =SUMIFS(LEMBUR!$F$4:$F$235,LEMBUR!$B$4:$B$235,ABSENSI!$B43) -> 0 | M43: =COUNTIF(R43:BA43,"√√")+COUNTIF(R43:BA43,"X/") -> 0 | N43: =COUNTIF(S43:BA43,"√/") -> 0 | O43: =N43*0.5 -> 0 | P43: =SUM(Q43:S43)+O43 -> 23 | Q43: =(COUNTIF(W43:BA43,"√"))+(COUNTIF(W43:BA43,"√√")) -> 23 | R43: =COUNTIF(W43:BA43,"s") -> 0 | S43: =COUNTIF(W43:BA43,"c") -> 0 | T43: =COUNTIF(W43:BA43,"i") -> 0 | U43: =COUNTIF(W43:BA43,"") -> 3 | V43: =COUNTIF(W43:BA43,"X") -> 5 | W43: √ | X43: √ | Y43: √ | Z43: √ | AA43: X | AB43: √ | AC43: √ | AD43: √ | AE43: √ | AF43: √ | AG43: √ | AH43: X | AI43: √ | AJ43: √ | AK43: √ | AL43: √ | AM43: √ | AN43: √ | AO43: X | AP43: √ | AQ43: √ | AR43: X | AS43: X | AT43: √ | AU43: √ | AV43: √ | AW43: √ | AX43: √
...

Sheet LEMBUR
F2: =SUM(F4:F235) -> 265.5
A3: No. | B3: NAMA KARYAWAN | C3: TANGGAL LEMBUR | D3: AREA | E3: JAM | F3: DURASI LEMBUR | G3: ACC SPV | H3: ACC PERSONALIA
A4: 1 | B4: Septian Dewan Putra Pratama | C4: 46078 | D4: Tunjungan Plaza-In House Training | E4: 15:00-17:00 | F4: 1 | G4: Moch Anis Fatony
A5: 2 | B5: Nur Imam Siswo Utomo | C5: 46079 | D5: Tanamera-Fu sumber bau tikus | E5: 16:44-17:18 | F5: 1 | G5: Fahmi Idris Mangku Alam
A6: 3 | B6: M Gilang Isad Abdul Ghofur | C6: 46079 | D6: Tanamerah Coffe-Fu Bangkai tikus | E6: 16:00-17:00 | F6: 1 | G6: Fahmi Idris Mangku Alam
A7: 4 | B7: Suparman | C7: 46076 | D7: Pakuwon mall + PTC-Fogging asap | E7: 00:00-01:30 | F7: 1 | G7: Moch Anis Fatony
A8: 5 | B8: Argantara Alif Saputra | C8: 46080 | D8: PM Jogja-Install blackbox | E8: 16:00-00:00 | F8: 8 | G8: Fahmi Idris Mangku Alam
A9: 6 | B9: M Gilang Isad Abdul Ghofur | C9: 46080 | D9: PM Jogja-Install blackbox | E9: 16:00-00:00 | F9: 8 | G9: Fahmi Idris Mangku Alam
A10: 7 | B10: Argantara Alif Saputra | C10: 46081 | D10: pm jogja-pemindahan logistic & unit ke gudang | E10: 00:00-01:00 | F10: 1 | G10: Fahmi Idris Mangku Alam
A11: 8 | B11: Argantara Alif Saputra | C11: 46082 | D11: PM jogja-training/pendampingan teknisi baru shift pagi | E11: 07:00-15:00 | F11: 8 | G11: Fahmi Idris Mangku Alam
A12: 9 | B12: Fathur Rozek | C12: 46105 | D12: Office-Beres beres | E12: 10:00-13:00 | F12: 2 | G12: Fahmi Idris Mangku Alam
A13: 10 | B13: M Gilang Isad Abdul Ghofur | C13: 46082 | D13: PM solo-pendampingan teknisi solo | E13: 07:00-15:00 | F13: 8 | G13: Fahmi Idris Mangku Alam
A14: 11 | B14: Argantara Alif Saputra | C14: 46083 | D14: PM JOGJA-install unit flycatcher | E14: 23:00-01:00 | F14: 2 | G14: Fahmi Idris Mangku Alam
A15: 12 | B15: Ahmad Yusrin Najih | C15: 46083 | D15: PM-PTC-Meeting Pest Control | E15: 14:00-16:00 | F15: 2 | G15: Moch Anis Fatony
... A95: 92 | B95: Muliyasari | C95: 46106 | D95: Siti Utomo Kediri -Fum | E95: 16:00-20:00 | F95: 5 | G95: Fahmi Idris Mangku Alam
A96: 93
A97: 94
A98: 95
A99: 96
A100: 97
A101: 98
A102: 99
A103: 100
A104: 101
A105: 102
A106: 103
A107: 104
... A235: 232

Sheet KUNJUNGAN
C1: Copy C4 | H1: Copy H4 | I1: Copy I4 | J1: Copy J4 | K1: Copy K4
C2: Paste ke bawah | H2: Paste ke bawah | I2: Paste ke bawah | J2: Paste ke bawah | K2: Paste ke bawah
A3: No. | B3: NAMA KARYAWAN | C3: JUMLAH KUNJUNGAN | D3: CUSTOMER | E3: CHECK IN | F3: CHECK OUT | G3: DURASI | H3: JAM | I3: MENIT | J3: TOTAL WAKTU | K3: Cek | L3: ACC SPV | M3: ACC PERSONALIA
A4: 1 | B4: Choirul Anam | C4: 1 | D4: PT Heaven Chemical Indonesia | E4: 17 Mar 2026 - 13:06 | F4: 18 Mar 2026 - 00:40 | G4: 60 | H4: =ROUNDDOWN(KUNJUNGAN!$G4/60,0) -> 1 | I4: =G4-(H4*60) -> 0 | J4: =(KUNJUNGAN!$H4*60)+KUNJUNGAN!$I4 -> 60 | L4: Imelynia PS
A5: 2 | B5: Choirul Anam | C5: 1 | D5: STEVEN GUNARTO | E5: 02 Mar 2026 - 14:06 | F5: 03 Mar 2026 - 01:18 | G5: 60 | H5: =ROUNDDOWN(KUNJUNGAN!$G5/60,0) -> 1 | I5: =G5-(H5*60) -> 0 | J5: =(KUNJUNGAN!$H5*60)+KUNJUNGAN!$I5 -> 60 | L5: Imelynia PS
A6: 3 | B6: Choirul Anam | C6: 1 | D6: SPBU PANJANG JIWO | E6: 25 Mar 2026 - 15:49 | F6: 26 Mar 2026 - 01:44 | G6: 60 | H6: =ROUNDDOWN(KUNJUNGAN!$G6/60,0) -> 1 | I6: =G6-(H6*60) -> 0 | J6: =(KUNJUNGAN!$H6*60)+KUNJUNGAN!$I6 -> 60 | L6: Imelynia PS
A7: 4 | B7: Choirul Anam | C7: 1 | D7: CENTIMETER ADVERTISING | E7: 07 Mar 2026 - 10:46 | F7: 07 Mar 2026 - 19:12 | G7: 60 | H7: =ROUNDDOWN(KUNJUNGAN!$G7/60,0) -> 1 | I7: =G7-(H7*60) -> 0 | J7: =(KUNJUNGAN!$H7*60)+KUNJUNGAN!$I7 -> 60 | L7: Imelynia PS
A8: 5 | B8: Choirul Anam | C8: 1 | D8: DAYS SURABAYA | E8: 12 Mar 2026 - 21:39 | F8: 13 Mar 2026 - 04:00 | G8: 60 | H8: =ROUNDDOWN(KUNJUNGAN!$G8/60,0) -> 1 | I8: =G8-(H8*60) -> 0 | J8: =(KUNJUNGAN!$H8*60)+KUNJUNGAN!$I8 -> 60 | L8: Imelynia PS
A9: 6 | B9: Choirul Anam | C9: 1 | D9: Demandailing Jemursari | E9: 07 Mar 2026 - 12:56 | F9: 07 Mar 2026 - 19:14 | G9: 60 | H9: =ROUNDDOWN(KUNJUNGAN!$G9/60,0) -> 1 | I9: =G9-(H9*60) -> 0 | J9: =(KUNJUNGAN!$H9*60)+KUNJUNGAN!$I9 -> 60 | L9: Imelynia PS
A10: 7 | B10: Choirul Anam | C10: 1 | D10: GKI Darmo Satelit | E10: 05 Mar 2026 - 12:56 | F10: 05 Mar 2026 - 19:34 | G10: 60 | H10: =ROUNDDOWN(KUNJUNGAN!$G10/60,0) -> 1 | I10: =G10-(H10*60) -> 0 | J10: =(KUNJUNGAN!$H10*60)+KUNJUNGAN!$I10 -> 60 | L10: Imelynia PS
A11: 8 | B11: Choirul Anam | C11: 1 | D11: CV MANNA INDO LAKTA (SDA) | E11: 18 Mar 2026 - 09:42 | F11: 18 Mar 2026 - 15:07 | G11: 60 | H11: =ROUNDDOWN(KUNJUNGAN!$G11/60,0) -> 1 | I11: =G11-(H11*60) -> 0 | J11: =(KUNJUNGAN!$H11*60)+KUNJUNGAN!$I11 -> 60 | L11: Imelynia PS
A12: 9 | B12: Choirul Anam | C12: 1 | D12: Wiena Catering | E12: 18 Mar 2026 - 09:11 | F12: 18 Mar 2026 - 14:59 | G12: 60 | H12: =ROUNDDOWN(KUNJUNGAN!$G12/60,0) -> 1 | I12: =G12-(H12*60) -> 0 | J12: =(KUNJUNGAN!$H12*60)+KUNJUNGAN!$I12 -> 60 | L12: Imelynia PS
A13: 10 | B13: Choirul Anam | C13: 1 | D13: GKI Darmo Satelit | E13: 24 Mar 2026 - 11:44 | F13: 24 Mar 2026 - 16:04 | G13: 60 | H13: =ROUNDDOWN(KUNJUNGAN!$G13/60,0) -> 1 | I13: =G13-(H13*60) -> 0 | J13: =(KUNJUNGAN!$H13*60)+KUNJUNGAN!$I13 -> 60 | L13: Imelynia PS
A14: 11 | B14: Choirul Anam | C14: 1 | D14: PAK HENDRIK | E14: 28 Feb 2026 - 10:20 | F14: 28 Feb 2026 - 14:58 | G14: 60 | H14: =ROUNDDOWN(KUNJUNGAN!$G14/60,0) -> 1 | I14: =G14-(H14*60) -> 0 | J14: =(KUNJUNGAN!$H14*60)+KUNJUNGAN!$I14 -> 60 | L14: Imelynia PS
A15: 12 | B15: Choirul Anam | C15: 1 | D15: PT. Central Auto Perkasa | E15: 25 Mar 2026 - 10:36 | F15: 25 Mar 2026 - 15:07 | G15: 60 | H15: =ROUNDDOWN(KUNJUNGAN!$G15/60,0) -> 1 | I15: =G15-(H15*60) -> 0 | J15: =(KUNJUNGAN!$H15*60)+KUNJUNGAN!$I15 -> 60 | L15: Imelynia PS
... A151: 99 | B151: Lucky Adi Putra | C151: 1 | D151: SANTIKA PANDEGILING | E151: 12 Mar 2026 - 15:03 | F151: 13 Mar 2026 - 00:02 | G151: 120 | H151: =ROUNDDOWN(KUNJUNGAN!$G151/60,0) -> 2 | I151: =G151-(H151*60) -> 0 | J151: =(KUNJUNGAN!$H151*60)+KUNJUNGAN!$I151 -> 120 | L151: Imelynia PS
A152: 100 | B152: Lucky Adi Putra | C152: 1 | D152: SANTIKA PANDEGILING | E152: 25 Mar 2026 - 23:37 | G152: 180 | H152: =ROUNDDOWN(KUNJUNGAN!$G152/60,0) -> 3 | I152: =G152-(H152*60) -> 0 | J152: =(KUNJUNGAN!$H152*60)+KUNJUNGAN!$I152 -> 180 | L152: Imelynia PS
A153: 101 | B153: Lucky Adi Putra | C153: 1 | D153: SANTIKA PANDEGILING | E153: 27 Feb 2026 - 00:56 | F153: 27 Feb 2026 - 01:52 | G153: 55 | H153: =ROUNDDOWN(KUNJUNGAN!$G153/60,0) -> 0 | I153: =G153-(H153*60) -> 55 | J153: =(KUNJUNGAN!$H153*60)+KUNJUNGAN!$I153 -> 55 | L153: Imelynia PS
A154: 102 | B154: Lucky Adi Putra | C154: 1 | D154: SON GA KOREAN RESTO | E154: 17 Mar 2026 - 21:31 | F154: 18 Mar 2026 - 02:55 | G154: 90 | H154: =ROUNDDOWN(KUNJUNGAN!$G154/60,0) -> 1 | I154: =G154-(H154*60) -> 30 | J154: =(KUNJUNGAN!$H154*60)+KUNJUNGAN!$I154 -> 90 | L154: Imelynia PS
A155: 103 | B155: Lucky Adi Putra | C155: 1 | D155: SON GA KOREAN RESTO | E155: 10 Mar 2026 - 21:19 | F155: 11 Mar 2026 - 02:15 | G155: 90 | H155: =ROUNDDOWN(KUNJUNGAN!$G155/60,0) -> 1 | I155: =G155-(H155*60) -> 30 | J155: =(KUNJUNGAN!$H155*60)+KUNJUNGAN!$I155 -> 90 | L155: Imelynia PS
A156: 137 | B156: Lucky Adi Putra | C156: 1 | D156: SON GA KOREAN RESTO | E156: 03 Mar 2026 - 21:26 | F156: 04 Mar 2026 - 01:52 | G156: 90 | H156: =ROUNDDOWN(KUNJUNGAN!$G156/60,0) -> 1 | I156: =G156-(H156*60) -> 30 | J156: =(KUNJUNGAN!$H156*60)+KUNJUNGAN!$I156 -> 90 | L156: Imelynia PS
A157: 104 | B157: Lucky Adi Putra | C157: 1 | D157: SON GA KOREAN RESTO | E157: 24 Mar 2026 - 21:14 | F157: 25 Mar 2026 - 00:17 | G157: 90 | H157: =ROUNDDOWN(KUNJUNGAN!$G157/60,0) -> 1 | I157: =G157-(H157*60) -> 30 | J157: =(KUNJUNGAN!$H157*60)+KUNJUNGAN!$I157 -> 90 | L157: Imelynia PS
A158: 105 | B158: Lucky Adi Putra | C158: 1 | D158: TRISTAR RESTAURANT | E158: 26 Feb 2026 - 08:47 | F158: 27 Feb 2026 - 01:38 | G158: 180 | H158: =ROUNDDOWN(KUNJUNGAN!$G158/60,0) -> 3 | I158: =G158-(H158*60) -> 0 | J158: =(KUNJUNGAN!$H158*60)+KUNJUNGAN!$I158 -> 180 | L158: Imelynia PS
A159: 106 | B159: Lucky Adi Putra | C159: 1 | D159: TRISTAR RESTAURANT | E159: 17 Mar 2026 - 09:04 | F159: 17 Mar 2026 - 20:23 | G159: 60 | H159: =ROUNDDOWN(KUNJUNGAN!$G159/60,0) -> 1 | I159: =G159-(H159*60) -> 0 | J159: =(KUNJUNGAN!$H159*60)+KUNJUNGAN!$I159 -> 60 | L159: Imelynia PS
A160: 107 | B160: Lucky Adi Putra | C160: 1 | D160: TRISTAR RESTAURANT | E160: 10 Mar 2026 - 08:59 | F160: 10 Mar 2026 - 14:18 | G160: 60 | H160: =ROUNDDOWN(KUNJUNGAN!$G160/60,0) -> 1 | I160: =G160-(H160*60) -> 0 | J160: =(KUNJUNGAN!$H160*60)+KUNJUNGAN!$I160 -> 60 | L160: Imelynia PS
A161: 139 | B161: Lucky Adi Putra | C161: 1 | D161: TRISTAR RESTAURANT | E161: 03 Mar 2026 - 09:03 | F161: 03 Mar 2026 - 11:44 | G161: 160 | H161: =ROUNDDOWN(KUNJUNGAN!$G161/60,0) -> 2 | I161: =G161-(H161*60) -> 40 | J161: =(KUNJUNGAN!$H161*60)+KUNJUNGAN!$I161 -> 160 | L161: Imelynia PS
A162: 108 | B162: Lucky Adi Putra | C162: 1 | D162: TRISTAR RESTAURANT | E162: 04 Mar 2026 - 13:24 | F162: 04 Mar 2026 - 13:33 | G162: 8 | H162: =ROUNDDOWN(KUNJUNGAN!$G162/60,0) -> 0 | I162: =G162-(H162*60) -> 8 | J162: =(KUNJUNGAN!$H162*60)+KUNJUNGAN!$I162 -> 8 | L162: Imelynia PS
A163: 109 | B163: Lucky Adi Putra | C163: 1 | D163: tuju dermaga seafood restaurant | E163: 05 Mar 2026 - 09:37 | F163: 06 Mar 2026 - 00:28 | G163: 60 | H163: =ROUNDDOWN(KUNJUNGAN!$G163/60,0) -> 1 | I163: =G163-(H163*60) -> 0 | J163: =(KUNJUNGAN!$H163*60)+KUNJUNGAN!$I163 -> 60 | L163: Imelynia PS
A164: 110 | B164: Lucky Adi Putra | C164: 1 | D164: tuju dermaga seafood restaurant | E164: 26 Feb 2026 - 21:59 | F164: 27 Feb 2026 - 01:43 | G164: 90 | H164: =ROUNDDOWN(KUNJUNGAN!$G164/60,0) -> 1 | I164: =G164-(H164*60) -> 30 | J164: =(KUNJUNGAN!$H164*60)+KUNJUNGAN!$I164 -> 90 | L164: Imelynia PS
... A167: 112 | B167: Lucky Adi Putra | C167: 1 | D167: Xiao Xiang Hunan Cuisine | E167: 04 Mar 2026 - 21:33 | F167: 04 Mar 2026 - 22:44 | G167: 71 | H167: =ROUNDDOWN(KUNJUNGAN!$G167/60,0) -> 1 | I167: =G167-(H167*60) -> 11 | J167: =(KUNJUNGAN!$H167*60)+KUNJUNGAN!$I167 -> 71 | L167: Imelynia PS
A168: 113 | B168: Lucky Adi Putra | C168: 1 | D168: SEKOLAH CIKAL SURABAYA | E168: 17 Mar 2026 - 15:12 | G168: 180 | H168: =ROUNDDOWN(KUNJUNGAN!$G168/60,0) -> 3 | I168: =G168-(H168*60) -> 0 | J168: =(KUNJUNGAN!$H168*60)+KUNJUNGAN!$I168 -> 180 | L168: Imelynia PS
A169: 114 | B169: Lucky Adi Putra | C169: 1 | D169: SEKOLAH CIKAL SURABAYA | E169: 14 Mar 2026 - 15:06 | G169: 180 | H169: =ROUNDDOWN(KUNJUNGAN!$G169/60,0) -> 3 | I169: =G169-(H169*60) -> 0 | J169: =(KUNJUNGAN!$H169*60)+KUNJUNGAN!$I169 -> 180 | L169: Imelynia PS
A170: 115 | B170: Lucky Adi Putra | C170: 1 | D170: SEKOLAH CIKAL SURABAYA | E170: 07 Mar 2026 - 14:56 | G170: 180 | H170: =ROUNDDOWN(KUNJUNGAN!$G170/60,0) -> 3 | I170: =G170-(H170*60) -> 0 | J170: =(KUNJUNGAN!$H170*60)+KUNJUNGAN!$I170 -> 180 | L170: Imelynia PS
A171: 116 | B171: Lucky Adi Putra | C171: 1 | D171: SEKOLAH CIKAL SURABAYA | E171: 28 Feb 2026 - 14:54 | F171: 07 Mar 2026 - 16:08 | G171: 180 | H171: =ROUNDDOWN(KUNJUNGAN!$G171/60,0) -> 3 | I171: =G171-(H171*60) -> 0 | J171: =(KUNJUNGAN!$H171*60)+KUNJUNGAN!$I171 -> 180 | L171: Imelynia PS
A172: 135 | B172: Muhammad Abu Samsudin | C172: 1 | D172: Acaii Tea Tunjungan Plaza | E172: 17 Mar 2026 - 20:56 | F172: 17 Mar 2026 - 22:09 | G172: 73 | H172: =ROUNDDOWN(KUNJUNGAN!$G172/60,0) -> 1 | I172: =G172-(H172*60) -> 13 | J172: =(KUNJUNGAN!$H172*60)+KUNJUNGAN!$I172 -> 73 | L172: Imelynia PS
